Workbook

Sheet Kuesioner Expert 3
B6: Pemilihan Berdasarkan Kriteria
B7: Kriteria | C7: Kriteria Nilai | T7: Kriteria | V7: Kriteria | W7: Ekonomi | X7: Lingkungan | Y7: Etika | Z7: Sosial
C8: 9 | D8: 8 | E8: 7 | F8: 6 | G8: 5 | H8: 4 | I8: 3 | J8: 2 | K8: 1 | L8: 2 | M8: 3 | N8: 4 | O8: 5 | P8: 6 | Q8: 7 | R8: 8 | S8: 9 | V8: Ekonomi | W8: 1 | X8: =1/7 -> 0.14285714 | Y8: 3 | Z8: 3
B9: Faktor Ekonomi | Q9: x | T9: Faktor Lingkungan | V9: Lingkungan | W9: =1/X8 -> 7 | X9: 1 | Y9: 5 | Z9: 7
B10: Faktor Ekonomi | I10: x | T10: Faktor Sosial | V10: Etika | W10: =1/Y8 -> 0.33333333 | X10: =1/Y9 -> 0.2 | Y10: 1 | Z10: 7
B11: Faktor Ekonomi | I11: x | T11: Faktor Etika | V11: Sosial | W11: =1/Z8 -> 0.33333333 | X11: =1/Z9 -> 0.14285714 | Y11: =1/Z10 -> 0.14285714 | Z11: 1
B12: Faktor Lingkungan | E12: x | T12: Faktor Sosial
B13: Faktor Lingkungan | G13: x | T13: Faktor Etika
B14: Faktor Sosial | E14: x | T14: Faktor Etika
B16: Pemilihan Berdasarkan Sub-kriteria pada Faktor Ekonomi
B17: Sub-kriteria | C17: Kriteria Nilai | T17: Sub-kriteria | V17: Subkriteria | W17: Kualitas | X17: Harga | Y17: Pengiriman | Z17: TKDN
C18: 9 | D18: 8 | E18: 7 | F18: 6 | G18: 5 | H18: 4 | I18: 3 | J18: 2 | K18: 1 | L18: 2 | M18: 3 | N18: 4 | O18: 5 | P18: 6 | Q18: 7 | R18: 8 | S18: 9 | V18: Kualitas | W18: 1 | X18: 5 | Y18: 5 | Z18: 5
B19: Kualitas | G19: x | T19: Harga | V19: Harga | W19: =1/X18 -> 0.2 | X19: 1 | Y19: 3 | Z19: 3
B20: Kualitas | G20: x | T20: Pengiriman (Delivery) | V20: Pengiriman | W20: =1/Y18 -> 0.2 | X20: =1/Y19 -> 0.33333333 | Y20: 1 | Z20: =1/5 -> 0.2
B21: Kualitas | G21: x | T21: TKDN | V21: TKDN | W21: =1/Z18 -> 0.2 | X21: =1/Z19 -> 0.33333333 | Y21: =1/Z20 -> 5 | Z21: 1
B22: Harga | I22: x | T22: Pengiriman (Delivery)
B23: Harga | I23: x | T23: TKDN (Tingkat Komponen Dalam Negeri)
B24: Pengiriman (Delivery) | O24: x | T24: TKDN (Tingkat Komponen Dalam Negeri)
B26: Pemilihan Berdasarkan Sub-kriteria pada Faktor Lingkungan
B27: Sub-kriteria | C27: Kriteria Nilai | T27: Sub-kriteria | V27: Subkriteria | W27: Eco-Design | X27: SML | Y27: Green Image
C28: 9 | D28: 8 | E28: 7 | F28: 6 | G28: 5 | H28: 4 | I28: 3 | J28: 2 | K28: 1 | L28: 2 | M28: 3 | N28: 4 | O28: 5 | P28: 6 | Q28: 7 | R28: 8 | S28: 9 | V28: Eco-Design | W28: 1 | X28: =1/7 -> 0.14285714 | Y28: =1/3 -> 0.33333333
B29: Eco-Design | Q29: x | T29: Sistem Manajemen Lingkungan | V29: SML | W29: =1/X28 -> 7 | X29: 1 | Y29: 3
B30: Eco-Design | M30: x | T30: Green Image | V30: Green Image | W30: =1/Y28 -> 3 | X30: =1/Y29 -> 0.33333333 | Y30: 1
B31: Sistem Manajemen Lingkungan | I31: x | T31: Green Image
B33: Pemilihan Berdasarkan Sub-kriteria pada Faktor Sosial
B34: Sub-kriteria | C34: Kriteria Nilai | T34: Sub-kriteria | V34: Subkriteria | W34: SKK | X34: CSR | Y34: ET
C35: 9 | D35: 8 | E35: 7 | F35: 6 | G35: 5 | H35: 4 | I35: 3 | J35: 2 | K35: 1 | L35: 2 | M35: 3 | N35: 4 | O35: 5 | P35: 6 | Q35: 7 | R35: 8 | S35: 9 | V35: SKK | W35: 1 | X35: 7 | Y35: 5
B36: Sistem Kesehatan dan Keselamatan Kerja | E36: x | T36: Corporate Social Responsibility (CSR) | V36: CSR | W36: =1/X35 -> 0.14285714 | X36: 1 | Y36: 5
B37: Sistem Kesehatan dan Keselamatan Kerja | G37: x | T37: Education & Training | V37: ET | W37: =1/Y35 -> 0.2 | X37: =1/Y36 -> 0.2 | Y37: 1
B38: Corporate Social Responsibility (CSR) | G38: x | T38: Education & Training
B40: Pemilihan Berdasarkan Sub-kriteria pada Faktor Etika
B41: Sub-kriteria | C41: Kriteria Nilai | T41: Sub-kriteria | V41: Subkriteria | W41: CoC | X41: Col | Y41: TAB
C42: 9 | D42: 8 | E42: 7 | F42: 6 | G42: 5 | H42: 4 | I42: 3 | J42: 2 | K42: 1 | L42: 2 | M42: 3 | N42: 4 | O42: 5 | P42: 6 | Q42: 7 | R42: 8 | S42: 9 | V42: CoC | W42: 1 | X42: 5 | Y42: 5
B43: Code of Conduct (CoC) | G43: x | T43: Conflict of Interest (CoI) | V43: Col | W43: =1/X42 -> 0.2 | X43: 1 | Y43: 5
B44: Code of Conduct (CoC) | G44: x | T44: Transparasi dalam akuntansi dan bisnis | V44: TAB | W44: =1/Y42 -> 0.2 | X44: =1/Y43 -> 0.2 | Y44: 1
B45: Conflict of Interest (CoI) | G45: x | T45: Transparasi dalam akuntansi dan bisnis

Sheet Kuesioner Expert 2
B6: Pemilihan Berdasarkan Kriteria
B7: Kriteria | C7: Kriteria Nilai | T7: Kriteria | V7: Kriteria | W7: Ekonomi | X7: Lingkungan | Y7: Etika | Z7: Sosial
C8: 9 | D8: 8 | E8: 7 | F8: 6 | G8: 5 | H8: 4 | I8: 3 | J8: 2 | K8: 1 | L8: 2 | M8: 3 | N8: 4 | O8: 5 | P8: 6 | Q8: 7 | R8: 8 | S8: 9 | V8: Ekonomi | W8: 1 | X8: =1/7 -> 0.14285714 | Y8: 1 | Z8: 5
B9: Faktor Ekonomi | Q9: x | T9: Faktor Lingkungan | V9: Lingkungan | W9: =1/X8 -> 7 | X9: 1 | Y9: =1/3 -> 0.33333333 | Z9: 1
B10: Faktor Ekonomi | G10: x | T10: Faktor Sosial | V10: Etika | W10: =1/Y8 -> 1 | X10: =1/Y9 -> 3 | Y10: 1 | Z10: 5
B11: Faktor Ekonomi | K11: x | T11: Faktor Etika | V11: Sosial | W11: =1/Z8 -> 0.2 | X11: =1/Z9 -> 1 | Y11: =1/Z10 -> 0.2 | Z11: 1
B12: Faktor Lingkungan | K12: x | T12: Faktor Sosial
B13: Faktor Lingkungan | M13: x | T13: Faktor Etika
B14: Faktor Sosial | G14: x | T14: Faktor Etika
B16: Pemilihan Berdasarkan Sub-kriteria pada Faktor Ekonomi
B17: Sub-kriteria | C17: Kriteria Nilai | T17: Sub-kriteria | V17: Subkriteria | W17: Kualitas | X17: Harga | Y17: Pengiriman | Z17: TKDN
C18: 9 | D18: 8 | E18: 7 | F18: 6 | G18: 5 | H18: 4 | I18: 3 | J18: 2 | K18: 1 | L18: 2 | M18: 3 | N18: 4 | O18: 5 | P18: 6 | Q18: 7 | R18: 8 | S18: 9 | V18: Kualitas | W18: 1 | X18: 7 | Y18: 5 | Z18: 5
B19: Kualitas | E19: x | T19: Harga | V19: Harga | W19: =1/X18 -> 0.14285714 | X19: 1 | Y19: 1 | Z19: =1/3 -> 0.33333333
B20: Kualitas | G20: x | T20: Pengiriman (Delivery) | V20: Pengiriman | W20: =1/Y18 -> 0.2 | X20: =1/Y19 -> 1 | Y20: 1 | Z20: 3
B21: Kualitas | G21: x | T21: TKDN | V21: TKDN | W21: =1/Z18 -> 0.2 | X21: =1/Z19 -> 3 | Y21: =1/Z20 -> 0.33333333 | Z21: 1
B22: Harga | K22: x | T22: Pengiriman (Delivery)
B23: Harga | M23: x | T23: TKDN (Tingkat Komponen Dalam Negeri)
B24: Pengiriman (Delivery) | I24: x | T24: TKDN (Tingkat Komponen Dalam Negeri)
B26: Pemilihan Berdasarkan Sub-kriteria pada Faktor Lingkungan
B27: Sub-kriteria | C27: Kriteria Nilai | T27: Sub-kriteria | V27: Subkriteria | W27: Eco-Design | X27: SML | Y27: Green Image
C28: 9 | D28: 8 | E28: 7 | F28: 6 | G28: 5 | H28: 4 | I28: 3 | J28: 2 | K28: 1 | L28: 2 | M28: 3 | N28: 4 | O28: 5 | P28: 6 | Q28: 7 | R28: 8 | S28: 9 | V28: Eco-Design | W28: 1 | X28: 1 | Y28: 3
B29: Eco-Design | K29: x | T29: Sistem Manajemen Lingkungan | V29: SML | W29: =1/X28 -> 1 | X29: 1 | Y29: 1
B30: Eco-Design | I30: x | T30: Green Image | V30: Green Image | W30: =1/Y28 -> 0.33333333 | X30: =1/Y29 -> 1 | Y30: 1
B31: Sistem Manajemen Lingkungan | K31: x | T31: Green Image
B33: Pemilihan Berdasarkan Sub-kriteria pada Faktor Sosial
B34: Sub-kriteria | C34: Kriteria Nilai | T34: Sub-kriteria | V34: Subkriteria | W34: SKK | X34: CSR | Y34: ET
C35: 9 | D35: 8 | E35: 7 | F35: 6 | G35: 5 | H35: 4 | I35: 3 | J35: 2 | K35: 1 | L35: 2 | M35: 3 | N35: 4 | O35: 5 | P35: 6 | Q35: 7 | R35: 8 | S35: 9 | V35: SKK | W35: 1 | X35: 7 | Y35: 1
B36: Sistem Kesehatan dan Keselamatan Kerja | E36: x | T36: Corporate Social Responsibility (CSR) | V36: CSR | W36: =1/X35 -> 0.14285714 | X36: 1 | Y36: 5
B37: Sistem Kesehatan dan Keselamatan Kerja | K37: x | T37: Education & Training | V37: ET | W37: =1/Y35 -> 1 | X37: =1/Y36 -> 0.2 | Y37: 1
B38: Corporate Social Responsibility (CSR) | G38: x | T38: Education & Training
B40: Pemilihan Berdasarkan Sub-kriteria pada Faktor Etika
B41: Sub-kriteria | C41: Kriteria Nilai | T41: Sub-kriteria | V41: Subkriteria | W41: CoC | X41: Col | Y41: TAB
C42: 9 | D42: 8 | E42: 7 | F42: 6 | G42: 5 | H42: 4 | I42: 3 | J42: 2 | K42: 1 | L42: 2 | M42: 3 | N42: 4 | O42: 5 | P42: 6 | Q42: 7 | R42: 8 | S42: 9 | V42: CoC | W42: 1 | X42: 9 | Y42: 1
B43: Code of Conduct (CoC) | C43: x | T43: Conflict of Interest (CoI) | V43: Col | W43: =1/X42 -> 0.11111111 | X43: 1 | Y43: 1
B44: Code of Conduct (CoC) | K44: x | T44: Transparasi dalam akuntansi dan bisnis | V44: TAB | W44: =1/Y42 -> 1 | X44: =1/Y43 -> 1 | Y44: 1
B45: Conflict of Interest (CoI) | K45: x | T45: Transparasi dalam akuntansi dan bisnis

Sheet Kuesioner Expert 1
B6: Pemilihan Berdasarkan Kriteria
B7: Kriteria | C7: Kriteria Nilai | T7: Kriteria | V7: Kriteria | W7: Ekonomi | X7: Lingkungan | Y7: Etika | Z7: Sosial
C8: 9 | D8: 8 | E8: 7 | F8: 6 | G8: 5 | H8: 4 | I8: 3 | J8: 2 | K8: 1 | L8: 2 | M8: 3 | N8: 4 | O8: 5 | P8: 6 | Q8: 7 | R8: 8 | S8: 9 | V8: Ekonomi | W8: 1 | X8: 7 | Y8: 7 | Z8: 7
B9: Faktor Ekonomi | E9: x | T9: Faktor Lingkungan | V9: Lingkungan | W9: =1/X8 -> 0.14285714 | X9: 1 | Y9: 5 | Z9: 1
B10: Faktor Ekonomi | E10: x | T10: Faktor Sosial | V10: Etika | W10: =1/Y8 -> 0.14285714 | X10: =1/Y9 -> 0.2 | Y10: 1 | Z10: 5
B11: Faktor Ekonomi | E11: x | T11: Faktor Etika | V11: Sosial | W11: =1/Z8 -> 0.14285714 | X11: =1/Z9 -> 1 | Y11: =1/Z10 -> 0.2 | Z11: 1
B12: Faktor Lingkungan | K12: x | T12: Faktor Sosial
B13: Faktor Lingkungan | G13: x | T13: Faktor Etika
B14: Faktor Sosial | G14: x | T14: Faktor Etika
B16: Pemilihan Berdasarkan Sub-kriteria pada Faktor Ekonomi
B17: Sub-kriteria | C17: Kriteria Nilai | T17: Sub-kriteria | V17: Subkriteria | W17: Kualitas | X17: Harga | Y17: Pengiriman | Z17: TKDN
C18: 9 | D18: 8 | E18: 7 | F18: 6 | G18: 5 | H18: 4 | I18: 3 | J18: 2 | K18: 1 | L18: 2 | M18: 3 | N18: 4 | O18: 5 | P18: 6 | Q18: 7 | R18: 8 | S18: 9 | V18: Kualitas | W18: 1 | X18: =1/9 -> 0.11111111 | Y18: 1 | Z18: 7
B19: Kualitas | S19: x | T19: Harga | V19: Harga | W19: =1/X18 -> 9 | X19: 1 | Y19: 5 | Z19: 7
B20: Kualitas | K20: x | T20: Pengiriman (Delivery) | V20: Pengiriman | W20: =1/Y18 -> 1 | X20: =1/Y19 -> 0.2 | Y20: 1 | Z20: 7
B21: Kualitas | E21: x | T21: TKDN | V21: TKDN | W21: =1/Z18 -> 0.14285714 | X21: =1/Z19 -> 0.14285714 | Y21: =1/Z20 -> 0.14285714 | Z21: 1
B22: Harga | G22: x | T22: Pengiriman (Delivery)
B23: Harga | E23: x | T23: TKDN (Tingkat Komponen Dalam Negeri)
B24: Pengiriman (Delivery) | E24: x | T24: TKDN (Tingkat Komponen Dalam Negeri)
B26: Pemilihan Berdasarkan Sub-kriteria pada Faktor Lingkungan
B27: Sub-kriteria | C27: Kriteria Nilai | T27: Sub-kriteria | V27: Subkriteria | W27: Eco-Design | X27: SML | Y27: Green Image
C28: 9 | D28: 8 | E28: 7 | F28: 6 | G28: 5 | H28: 4 | I28: 3 | J28: 2 | K28: 1 | L28: 2 | M28: 3 | N28: 4 | O28: 5 | P28: 6 | Q28: 7 | R28: 8 | S28: 9 | V28: Eco-Design | W28: 1 | X28: =1/7 -> 0.14285714 | Y28: =1/7 -> 0.14285714
B29: Eco-Design | Q29: x | T29: Sistem Manajemen Lingkungan | V29: SML | W29: =1/X28 -> 7 | X29: 1 | Y29: 7
B30: Eco-Design | Q30: x | T30: Green Image | V30: Green Image | W30: =1/Y28 -> 7 | X30: =1/Y29 -> 0.14285714 | Y30: 1
B31: Sistem Manajemen Lingkungan | E31: x | T31: Green Image
B33: Pemilihan Berdasarkan Sub-kriteria pada Faktor Sosial
B34: Sub-kriteria | C34: Kriteria Nilai | T34: Sub-kriteria | V34: Subkriteria | W34: SKK | X34: CSR | Y34: ET
C35: 9 | D35: 8 | E35: 7 | F35: 6 | G35: 5 | H35: 4 | I35: 3 | J35: 2 | K35: 1 | L35: 2 | M35: 3 | N35: 4 | O35: 5 | P35: 6 | Q35: 7 | R35: 8 | S35: 9 | V35: SKK | W35: 1 | X35: 7 | Y35: 7
B36: Sistem Kesehatan dan Keselamatan Kerja | E36: x | T36: Corporate Social Responsibility (CSR) | V36: CSR | W36: =1/X35 -> 0.14285714 | X36: 1 | Y36: 1
B37: Sistem Kesehatan dan Keselamatan Kerja | E37: x | T37: Education & Training | V37: ET | W37: =1/Y35 -> 0.14285714 | X37: =1/Y36 -> 1 | Y37: 1
B38: Corporate Social Responsibility (CSR) | K38: x | T38: Education & Training
B40: Pemilihan Berdasarkan Sub-kriteria pada Faktor Etika
B41: Sub-kriteria | C41: Kriteria Nilai | T41: Sub-kriteria | V41: Subkriteria | W41: CoC | X41: Col | Y41: TAB
C42: 9 | D42: 8 | E42: 7 | F42: 6 | G42: 5 | H42: 4 | I42: 3 | J42: 2 | K42: 1 | L42: 2 | M42: 3 | N42: 4 | O42: 5 | P42: 6 | Q42: 7 | R42: 8 | S42: 9 | V42: CoC | W42: 1 | X42: 1 | Y42: 1
B43: Code of Conduct (CoC) | K43: x | T43: Conflict of Interest (CoI) | V43: Col | W43: =1/X42 -> 1 | X43: 1 | Y43: 1
B44: Code of Conduct (CoC) | K44: x | T44: Transparasi dalam akuntansi dan bisnis | V44: TAB | W44: =1/Y42 -> 1 | X44: =1/Y43 -> 1 | Y44: 1
B45: Conflict of Interest (CoI) | K45: x | T45: Transparasi dalam akuntansi dan bisnis

Sheet Supplier Info
B2: Alternatives Supplier | C2: EKONOMI | G2: LINGKUNGAN | J2: SOSIAL | M2: ETIKA
C3: Kualitas | D3: Harga | E3: Delivery | F3: TKDN | G3: Eco-design | H3: Sistem Man. Lingkungan | I3: Green Image | J3: Sistem K3 | K3: CSR | L3: Education & Training | M3: CoC | N3: CoI | O3: Transparansi Akuntansi Bisnis
C4: DPMO | D4: USD | E4: Days | F4: % | G4: High-Low (Rating 0-7) | H4: High-Low (Rating 0-7) | I4: High-Low (Rating 0-7) | J4: Lost Time Injury Freq. Rate | K4: High-Low (Rating 0-7) | L4: No. of Training Sessions | M4: High-Low (Rating 0-7) | N4: No. of Cases | O4: Disclosure level
B5: S1 | C5: 200 | D5: 4500000 | E5: 180 | F5: 35 | G5: 7 | H5: 3 | I5: 7 | J5: 2 | K5: 5 | L5: 8 | M5: 6 | N5: 2 | O5: 1
B6: S2 | C6: 240 | D6: 4200000 | E6: 200 | F6: 40 | G6: 3 | H6: 5 | I6: 5 | J6: 1 | K6: 3 | L6: 5 | M6: 5 | N6: 5 | O6: 3
B7: S3 | C7: 160 | D7: 4800000 | E7: 200 | F7: 38 | G7: 5 | H7: 5 | I7: 6 | J7: 1 | K7: 7 | L7: 5 | M7: 7 | N7: 3 | O7: 5
B8: S4 | C8: 220 | D8: 4300000 | E8: 220 | F8: 45 | G8: 5 | H8: 7 | I8: 6 | J8: 2 | K8: 5 | L8: 7 | M8: 7 | N8: 0 | O8: 1
B9: S5 | C9: 180 | D9: 4600000 | E9: 220 | F9: 37 | G9: 5 | H9: 7 | I9: 5 | J9: 1 | K9: 7 | L9: 6 | M9: 5 | N9: 2 | O9: 3
C10: min | D10: min | E10: min | F10: max | G10: max | H10: max | I10: max | J10: min | K10: max | L10: max | M10: max | N10: min | O10: max
B12: Saran perbaikan:
B13: tambahkan expert di bagian HSE
B14: tambahkan subkriteria Polution Control, MCU procedure and records, and Human Rights
B15: tambahkan kriteria flexibility
B16: hubungan antara kriteria dan bobot kriteria
E40: 0.48
E41: 0.24
E42: 0.16
E43: 0.12
E44: =SUM(E40:E43) -> 1
M61: 0.1941
M62: 0.1567
M63: 0.0655
M64: 0.0331
M65: 0.0091
M66: 0.0528
M67: 0.0583
M68: 0.0171
M69: 0.0334
M70: 0.113
M71: 0.0803
M72: 0.039
... M76: 0.0401
M78: =SUM(M61:M77) -> 1

Sheet AHP
A1: Jumlah Elemen | B1: 1 | C1: 2 | D1: 3 | E1: 4 | F1: 5 | G1: 6 | H1: 7 | I1: 8 | J1: 9 | K1: 10 | L1: 11 | M1: 12
A2: Rasio Indeks | B2: 0 | C2: 0 | D2: 0.58 | E2: 0.9 | F2: 1.12 | G2: 1.24 | H2: 1.32 | I2: 1.41 | J2: 1.45 | K2: 1.49 | L2: 1.52 | M2: 1.54
A4: Perhitungan AHP Pada Kriteria
B5: Expert 1 Kuesioner
B6: Kriteria | C6: Ekonomi | D6: Lingkungan | E6: Etika | F6: Sosial
B7: Ekonomi | C7: 1 | D7: 7 | E7: 7 | F7: 7
B8: Lingkungan | C8: =1/D7 -> 0.14285714 | D8: 1 | E8: 5 | F8: 4
B9: Etika | C9: =1/E7 -> 0.14285714 | D9: =1/E8 -> 0.2 | E9: 1 | F9: 5
B10: Sosial | C10: =1/F7 -> 0.14285714 | D10: =1/F8 -> 0.25 | E10: =1/F9 -> 0.2 | F10: 1
B11: Expert 2 Kuesioner
B12: Kriteria | C12: Ekonomi | D12: Lingkungan | E12: Etika | F12: Sosial
B13: Ekonomi | C13: 1 | D13: =1/7 -> 0.14285714 | E13: 1 | F13: 5 | H13: Kriteria | I13: Ekonomi | J13: Lingkungan | K13: Etika | L13: Sosial
B14: Lingkungan | C14: =1/D13 -> 7 | D14: 1 | E14: =1/3 -> 0.33333333 | F14: 3 | H14: Ekonomi | I14: 1 | J14: =GEOMEAN(D7,D19,D13) -> 0.52275796 | K14: =GEOMEAN(E7,E19,E13) -> 2.7589242 | L14: =GEOMEAN(F7,F19,F13) -> 4.717694
B15: Etika | C15: =1/E13 -> 1 | D15: =1/E14 -> 3 | E15: 1 | F15: 5 | H15: Lingkungan | I15: =1/J14 -> 1.9129312 | J15: 1 | K15: =GEOMEAN(E8,E20,E14) -> 2.0274007 | L15: =GEOMEAN(F8,F20,F14) -> 4.3795191
B16: Sosial | C16: =1/F13 -> 0.2 | D16: =1/F14 -> 0.33333333 | E16: =1/F15 -> 0.2 | F16: 1 | H16: Etika | I16: =1/K14 -> 0.36246012 | J16: =1/K15 -> 0.49324241 | K16: 1 | L16: =GEOMEAN(F9,F21,F15) -> 5.5934447
B17: Expert 3 Kuesioner | H17: Sosial | I17: =1/L14 -> 0.21196797 | J17: =1/L15 -> 0.22833557 | K17: =1/L16 -> 0.17878071 | L17: 1
B18: Kriteria | C18: Ekonomi | D18: Lingkungan | E18: Etika | F18: Sosial | H18: Total | I18: =SUM(I14:I17) -> 3.4873593 | J18: =SUM(J14:J17) -> 2.2443359 | K18: =SUM(K14:K17) -> 5.9651055 | L18: =SUM(L14:L17) -> 15.690658
B19: Ekonomi | C19: 1 | D19: =1/7 -> 0.14285714 | E19: 3 | F19: 3
B20: Lingkungan | C20: =1/D19 -> 7 | D20: 1 | E20: 5 | F20: 7 | H20: Tabel Normalisasi
B21: Etika | C21: =1/E19 -> 0.33333333 | D21: =1/E20 -> 0.2 | E21: 1 | F21: 7 | H21: Kriteria | I21: Ekonomi | J21: Lingkungan | K21: Etika | L21: Sosial | M21: Priority Vector | N21: Hasil Kali | O21: HK/PV
B22: Sosial | C22: =1/F19 -> 0.33333333 | D22: =1/F20 -> 0.14285714 | E22: =1/F21 -> 0.14285714 | F22: 1 | H22: Ekonomi | I22: =I14/$I$18 -> 0.28674992 | J22: =J14/$J$18 -> 0.23292322 | K22: =K14/$K$18 -> 0.46251054 | L22: =L14/$L$18 -> 0.30066897 | M22: =SUM(I22:L22)/4 -> 0.32071316 | N22: =MMULT(I14:L14,$M$22:$M$25) -> 1.4184993 | O22: =N22/M22 -> 4.4229533
H23: Lingkungan | I23: =I15/$I$18 -> 0.54853287 | J23: =J15/$J$18 -> 0.44556609 | K23: =K15/$K$18 -> 0.33987675 | L23: =L15/$L$18 -> 0.27911635 | M23: =SUM(I23:L23)/4 -> 0.40327301 | N23: =MMULT(I15:L15,$M$22:$M$25) -> 1.7270329 | O23: =N23/M23 -> 4.2825403
H24: Etika | I24: =I16/$I$18 -> 0.10393541 | J24: =J16/$J$18 -> 0.2197721 | K24: =K16/$K$18 -> 0.16764163 | L24: =L16/$L$18 -> 0.35648249 | M24: =SUM(I24:L24)/4 -> 0.21195791 | N24: =MMULT(I16:L16,$M$22:$M$25) -> 0.88540822 | O24: =N24/M24 -> 4.1772833
H25: Sosial | I25: =I17/$I$18 -> 0.060781798 | J25: =J17/$J$18 -> 0.10173859 | K25: =K17/$K$18 -> 0.029971089 | L25: =L17/$L$18 -> 0.063732191 | M25: =SUM(I25:L25)/4 -> 0.064055916 | N25: =MMULT(I17:L17,$M$22:$M$25) -> 0.26201239 | O25: =N25/M25 -> 4.0903699
H26: Total | I26: =SUM(I22:I25) -> 1 | J26: =SUM(J22:J25) -> 1 | K26: =SUM(K22:K25) -> 1 | L26: =SUM(L22:L25) -> 1
O27: Lambda | P27: =AVERAGE(O22:O25) -> 4.2432867 | Q27: Kesimpulan
O28: Elemen | P28: 4 | Q28: =IF(P31<=0.1,"Konsisten","Tidak Konsisten") -> Konsisten
O29: CI | P29: =(P27-P28)/(P28-1) -> 0.081095565 | Q29: Note: Konsisten jika bernilai <= 0,1
O30: RI | P30: =$E$2 -> 0.9
O31: CR | P31: =P29/P30 -> 0.090106184
A34: Perhitungan AHP Pada Tiap-tiap Subkriteria
A35: Ekonomi
B36: Expert 1 Kuesioner
B37: Subkriteria | C37: Kualitas | D37: Harga | E37: Pengiriman | F37: TKDN
B38: Kualitas | C38: 1 | D38: =1/9 -> 0.11111111 | E38: 1 | F38: 7
B39: Harga | C39: =1/D38 -> 9 | D39: 1 | E39: 5 | F39: 7
B40: Pengiriman | C40: =1/E38 -> 1 | D40: =1/E39 -> 0.2 | E40: 1 | F40: 7
B41: TKDN | C41: =1/F38 -> 0.14285714 | D41: =1/F39 -> 0.14285714 | E41: =1/F40 -> 0.14285714 | F41: 1
B42: Expert 2 Kuesioner
B43: Subkriteria | C43: Kualitas | D43: Harga | E43: Pengiriman | F43: TKDN
...

Sheet AHP edit
A1: Jumlah Elemen | B1: 1 | C1: 2 | D1: 3 | E1: 4 | F1: 5 | G1: 6 | H1: 7 | I1: 8 | J1: 9 | K1: 10 | L1: 11 | M1: 12
A2: Rasio Indeks | B2: 0 | C2: 0 | D2: 0.58 | E2: 0.9 | F2: 1.12 | G2: 1.24 | H2: 1.32 | I2: 1.41 | J2: 1.45 | K2: 1.49 | L2: 1.52 | M2: 1.54
A4: Perhitungan AHP Pada Kriteria
B5: Expert 1 Kuesioner
B6: Kriteria | C6: Ekonomi | D6: Lingkungan | E6: Sosial | F6: Etika
B7: Ekonomi | C7: 1 | D7: 5 | E7: 3 | F7: 7
B8: Lingkungan | C8: =1/D7 -> 0.2 | D8: 1 | E8: 3 | F8: 5
B9: Sosial | C9: =1/E7 -> 0.33333333 | D9: =1/E8 -> 0.33333333 | E9: 1 | F9: 5
B10: Etika | C10: =1/F7 -> 0.14285714 | D10: =1/F8 -> 0.2 | E10: =1/F9 -> 0.2 | F10: 1
B11: Expert 2 Kuesioner
B12: Kriteria | C12: Ekonomi | D12: Lingkungan | E12: Sosial | F12: Etika
B13: Ekonomi | C13: 1 | D13: =1/3 -> 0.33333333 | E13: 3 | F13: 5 | H13: Kriteria | I13: Ekonomi | J13: Lingkungan | K13: Sosial | L13: Etika
B14: Lingkungan | C14: =1/D13 -> 3 | D14: 1 | E14: 3 | F14: 5 | H14: Ekonomi | I14: 1 | J14: =GEOMEAN(D7,D19,D13) -> 0.61979809 | K14: =GEOMEAN(E7,E19,E13) -> 3.9790572 | L14: =GEOMEAN(F7,F19,F13) -> 4.717694
B15: Sosial | C15: =1/E13 -> 0.33333333 | D15: =1/E14 -> 0.33333333 | E15: 1 | F15: 3 | H15: Lingkungan | I15: =1/J14 -> 1.6134286 | J15: 1 | K15: =GEOMEAN(E8,E20,E14) -> 3.5568933 | L15: =GEOMEAN(F8,F20,F14) -> 5.5934447
B16: Etika | C16: =1/F13 -> 0.2 | D16: =1/F14 -> 0.2 | E16: =1/F15 -> 0.33333333 | F16: 1 | H16: Sosial | I16: =1/K14 -> 0.25131581 | J16: =1/K15 -> 0.28114422 | K16: 1 | L16: =GEOMEAN(F9,F21,F15) -> 4.717694
B17: Expert 3 Kuesioner | H17: Etika | I17: =1/L14 -> 0.21196797 | J17: =1/L15 -> 0.17878071 | K17: =1/L16 -> 0.21196797 | L17: 1
B18: Kriteria | C18: Ekonomi | D18: Lingkungan | E18: Sosial | F18: Etika | H18: Total | I18: =SUM(I14:I17) -> 3.0767124 | J18: =SUM(J14:J17) -> 2.079723 | K18: =SUM(K14:K17) -> 8.7479185 | L18: =SUM(L14:L17) -> 16.028833
B19: Ekonomi | C19: 1 | D19: =1/7 -> 0.14285714 | E19: 7 | F19: 3
B20: Lingkungan | C20: =1/D19 -> 7 | D20: 1 | E20: 5 | F20: 7 | H20: Tabel Normalisasi
B21: Sosial | C21: =1/E19 -> 0.14285714 | D21: =1/E20 -> 0.2 | E21: 1 | F21: 7 | H21: Kriteria | I21: Ekonomi | J21: Lingkungan | K21: Sosial | L21: Etika | M21: Priority Vector | N21: Hasil Kali | O21: HK/PV
B22: Etika | C22: =1/F19 -> 0.33333333 | D22: =1/F20 -> 0.14285714 | E22: =1/F21 -> 0.14285714 | F22: 1 | H22: Ekonomi | I22: =I14/$I$18 -> 0.32502225 | J22: =J14/$J$18 -> 0.29801954 | K22: =K14/$K$18 -> 0.4548576 | L22: =L14/$L$18 -> 0.29432549 | M22: =SUM(I22:L22)/4 -> 0.34305622 | N22: =MMULT(I14:L14,$M$22:$M$25) -> 1.5229233 | O22: =N22/M22 -> 4.439282
H23: Lingkungan | I23: =I15/$I$18 -> 0.52440021 | J23: =J15/$J$18 -> 0.48083326 | K23: =K15/$K$18 -> 0.40659882 | L23: =L15/$L$18 -> 0.34896145 | M23: =SUM(I23:L23)/4 -> 0.44019843 | N23: =MMULT(I15:L15,$M$22:$M$25) -> 1.8875799 | O23: =N23/M23 -> 4.2880206
H24: Sosial | I24: =I16/$I$18 -> 0.081683232 | J24: =J16/$J$18 -> 0.13518349 | K24: =K16/$K$18 -> 0.11431291 | L24: =L16/$L$18 -> 0.29432549 | M24: =SUM(I24:L24)/4 -> 0.15637628 | N24: =MMULT(I16:L16,$M$22:$M$25) -> 0.65115376 | O24: =N24/M24 -> 4.1640187
H25: Etika | I25: =I17/$I$18 -> 0.068894306 | J25: =J17/$J$18 -> 0.08596371 | K25: =K17/$K$18 -> 0.024230675 | L25: =L17/$L$18 -> 0.062387575 | M25: =SUM(I25:L25)/4 -> 0.060369066 | N25: =MMULT(I17:L17,$M$22:$M$25) -> 0.24493174 | O25: =N25/M25 -> 4.0572392
H26: Total | I26: =SUM(I22:I25) -> 1 | J26: =SUM(J22:J25) -> 1 | K26: =SUM(K22:K25) -> 1 | L26: =SUM(L22:L25) -> 1
O27: Lambda | P27: =AVERAGE(O22:O25) -> 4.2371402 | Q27: Kesimpulan
O28: Elemen | P28: 4 | Q28: =IF(P31<=0.1,"Konsisten","Tidak Konsisten") -> Konsisten
O29: CI | P29: =(P27-P28)/(P28-1) -> 0.079046717 | Q29: Note: Konsisten jika bernilai <= 0,1
O30: RI | P30: =$E$2 -> 0.9
O31: CR | P31: =P29/P30 -> 0.087829685
A34: Perhitungan AHP Pada Tiap-tiap Subkriteria
A35: Ekonomi
B36: Expert 1 Kuesioner
B37: Subkriteria | C37: Kualitas | D37: Harga | E37: Pengiriman | F37: TKDN
B38: Kualitas | C38: 1 | D38: =1/9 -> 0.11111111 | E38: 1 | F38: 7
B39: Harga | C39: =1/D38 -> 9 | D39: 1 | E39: 5 | F39: 7
B40: Pengiriman | C40: =1/E38 -> 1 | D40: =1/E39 -> 0.2 | E40: 1 | F40: 7
B41: TKDN | C41: =1/F38 -> 0.14285714 | D41: =1/F39 -> 0.14285714 | E41: =1/F40 -> 0.14285714 | F41: 1
B42: Expert 2 Kuesioner
B43: Subkriteria | C43: Kualitas | D43: Harga | E43: Pengiriman | F43: TKDN
...

Sheet AHP-Topsis Mas Yandi
A1: Tabel Nilai Sub Kriteria
A3: Kriteria | B3: Sub Kriteria | E3: Tabel Alternatif dan Sub Kriteria
A4: Ekonomi C01 | B4: Kualitas | C4: ='[1]AHP edit'!M53/4 -> 0.11766992 | E4: Alternatives Supplier | F4: EKONOMI | J4: LINGKUNGAN | M4: SOSIAL | P4: ETIKA
B5: Harga | C5: ='[1]AHP edit'!M54/4 -> 0.070083903 | F5: Kualitas | G5: Harga | H5: Delivery | I5: TKDN | J5: Eco-design | K5: Sistem Man. Lingkungan | L5: Green Image | M5: Sistem K3 | N5: CSR | O5: Education & Training | P5: CoC | Q5: CoI | R5: Transparansi Akuntansi Bisnis
B6: Pengiriman | C6: ='[1]AHP edit'!M55/4 -> 0.036030333 | F6: DPMO | G6: USD | H6: Days | I6: % | J6: High-Low (Rating 0-7) | K6: High-Low (Rating 0-7) | L6: High-Low (Rating 0-7) | M6: Lost Time Injury Freq. Rate | N6: High-Low (Rating 0-7) | O6: No. of Training Sessions | P6: High-Low (Rating 0-7) | Q6: No. of Cases | R6: Disclosure level
B7: TKDN | C7: ='[1]AHP edit'!M56/4 -> 0.026215844 | E7: S1 | F7: 200 | G7: 4500000 | H7: 180 | I7: 35 | J7: 7 | K7: 3 | L7: 7 | M7: 2 | N7: 5 | O7: 8 | P7: 6 | Q7: 2 | R7: 1
A8: Lingkungan C02 | B8: Eco-Design | C8: ='[1]AHP edit'!K80/4 -> 0.036776077 | E8: S2 | F8: 240 | G8: 4200000 | H8: 200 | I8: 40 | J8: 3 | K8: 5 | L8: 5 | M8: 1 | N8: 3 | O8: 5 | P8: 5 | Q8: 5 | R8: 3
B9: SML | C9: ='[1]AHP edit'!K81/4 -> 0.15104027 | E9: S3 | F9: 160 | G9: 4800000 | H9: 200 | I9: 38 | J9: 5 | K9: 5 | L9: 6 | M9: 1 | N9: 7 | O9: 5 | P9: 7 | Q9: 3 | R9: 5
B10: Green Image | C10: ='[1]AHP edit'!K82/4 -> 0.062183657 | E10: S4 | F10: 220 | G10: 4300000 | H10: 220 | I10: 45 | J10: 5 | K10: 7 | L10: 6 | M10: 2 | N10: 5 | O10: 7 | P10: 7 | Q10: 0 | R10: 1
A11: Sosial C03 | B11: SKK | C11: ='[1]AHP edit'!K105/4 -> 0.14437087 | E11: S5 | F11: 180 | G11: 4600000 | H11: 220 | I11: 37 | J11: 5 | K11: 7 | L11: 5 | M11: 1 | N11: 7 | O11: 6 | P11: 5 | Q11: 2 | R11: 3
B12: CSR | C12: ='[1]AHP edit'!K106/4 -> 0.028456382
B13: ET | C13: ='[1]AHP edit'!K107/4 -> 0.077172748 | E13: Tabel Alternatif dan Sub Kriteria Kuadrat
A14: Etika C04 | B14: CoC | C14: ='[1]AHP edit'!K130/4 -> 0.12484218 | E14: Alternatives Supplier | F14: EKONOMI | J14: LINGKUNGAN | M14: SOSIAL | P14: ETIKA
B15: Col | C15: ='[1]AHP edit'!K131/4 -> 0.069788174 | F15: Kualitas | G15: Harga | H15: Delivery | I15: TKDN | J15: Eco-design | K15: Sistem Man. Lingkungan | L15: Green Image | M15: Sistem K3 | N15: CSR | O15: Education & Training | P15: CoC | Q15: CoI | R15: Transparansi Akuntansi Bisnis
B16: TAB | C16: ='[1]AHP edit'!K132/4 -> 0.055369649 | E16: S1 | F16: =F7^2 -> 40000 | G16: =G7^2 -> 20250000000000 | H16: =H7^2 -> 32400 | I16: =I7^2 -> 1225 | J16: =J7^2 -> 49 | K16: =K7^2 -> 9 | L16: =L7^2 -> 49 | M16: =M7^2 -> 4 | ... R16: =R7^2 -> 1
E17: S2 | F17: =F8^2 -> 57600 | G17: =G8^2 -> 17640000000000 | H17: =H8^2 -> 40000 | I17: =I8^2 -> 1600 | J17: =J8^2 -> 9 | K17: =K8^2 -> 25 | L17: =L8^2 -> 25 | M17: =M8^2 -> 1 | ... R17: =R8^2 -> 9
E18: S3 | F18: =F9^2 -> 25600 | G18: =G9^2 -> 23040000000000 | H18: =H9^2 -> 40000 | I18: =I9^2 -> 1444 | J18: =J9^2 -> 25 | K18: =K9^2 -> 25 | L18: =L9^2 -> 36 | M18: =M9^2 -> 1 | ... R18: =R9^2 -> 25
E19: S4 | F19: =F10^2 -> 48400 | G19: =G10^2 -> 18490000000000 | H19: =H10^2 -> 48400 | I19: =I10^2 -> 2025 | J19: =J10^2 -> 25 | K19: =K10^2 -> 49 | L19: =L10^2 -> 36 | M19: =M10^2 -> 4 | ... R19: =R10^2 -> 1
E20: S5 | F20: =F11^2 -> 32400 | G20: =G11^2 -> 21160000000000 | H20: =H11^2 -> 48400 | I20: =I11^2 -> 1369 | J20: =J11^2 -> 25 | K20: =K11^2 -> 49 | L20: =L11^2 -> 25 | M20: =M11^2 -> 1 | ... R20: =R11^2 -> 9
E22: Tabel Rata-rata Nilai Kriteria Ternormalisasi Terbobot
E23: Alternatives Supplier | F23: EKONOMI | J23: LINGKUNGAN | M23: SOSIAL | P23: ETIKA
F24: Kualitas | G24: Harga | H24: Delivery | I24: TKDN | J24: Eco-design | K24: Sistem Man. Lingkungan | L24: Green Image | M24: Sistem K3 | N24: CSR | O24: Education & Training | P24: CoC | Q24: CoI | R24: Transparansi Akuntansi Bisnis
E25: S1 | F25: =(F7/SQRT(SUM($F$16:$F$20)))*$C$4 -> 0.052105117 | G25: =(G7/SQRT(SUM($G$16:$G$20)))*$C$5 -> 0.031446693 | H25: =H7/SQRT(SUM($H$16:$H$20))*$C$6 -> 0.014179468 | I25: =I7/SQRT(SUM($I$16:$I$20))*$C$7 -> 0.010481718 | J25: =J7/SQRT(SUM($J$16:$J$20))*$C$8 -> 0.022322232 | K25: =K7/SQRT(SUM($K$16:$K$20))*$C$9 -> 0.036162976 | L25: =L7/SQRT(SUM($L$16:$L$20))*$C$10 -> 0.033287122 | M25: =M7/SQRT(SUM($M$16:$M$20))*$C$11 -> 0.08705891 | N25: =N7/SQRT(SUM($N$16:$N$20))*$C$12 -> 0.011355333 | O25: =O7/SQRT(SUM($O$16:$O$20))*$C$13 -> 0.043765048 | P25: =P7/SQRT(SUM($P$16:$P$20))*$C$14 -> 0.055220924 | Q25: =Q7/SQRT(SUM($Q$16:$Q$20))*$C$15 -> 0.021537098 | R25: =R7/SQRT(SUM($R$16:$R$20))*$C$16 -> 0.0082540199
E26: S2 | F26: =(F8/SQRT(SUM($F$16:$F$20)))*$C$4 -> 0.06252614 | G26: =(G8/SQRT(SUM($G$16:$G$20)))*$C$5 -> 0.029350246 | H26: =H8/SQRT(SUM($H$16:$H$20))*$C$6 -> 0.015754965 | I26: =I8/SQRT(SUM($I$16:$I$20))*$C$7 -> 0.011979106 | J26: =J8/SQRT(SUM($J$16:$J$20))*$C$8 -> 0.009566671 | K26: =K8/SQRT(SUM($K$16:$K$20))*$C$9 -> 0.060271627 | L26: =L8/SQRT(SUM($L$16:$L$20))*$C$10 -> 0.023776516 | M26: =M8/SQRT(SUM($M$16:$M$20))*$C$11 -> 0.043529455 | N26: =N8/SQRT(SUM($N$16:$N$20))*$C$12 -> 0.0068131996 | O26: =O8/SQRT(SUM($O$16:$O$20))*$C$13 -> 0.027353155 | P26: =P8/SQRT(SUM($P$16:$P$20))*$C$14 -> 0.046017437 | Q26: =Q8/SQRT(SUM($Q$16:$Q$20))*$C$15 -> 0.053842745 | R26: =R8/SQRT(SUM($R$16:$R$20))*$C$16 -> 0.02476206
E27: S3 | F27: =(F9/SQRT(SUM($F$16:$F$20)))*$C$4 -> 0.041684093 | G27: =(G9/SQRT(SUM($G$16:$G$20)))*$C$5 -> 0.033543139 | H27: =H9/SQRT(SUM($H$16:$H$20))*$C$6 -> 0.015754965 | I27: =I9/SQRT(SUM($I$16:$I$20))*$C$7 -> 0.011380151 | J27: =J9/SQRT(SUM($J$16:$J$20))*$C$8 -> 0.015944452 | K27: =K9/SQRT(SUM($K$16:$K$20))*$C$9 -> 0.060271627 | L27: =L9/SQRT(SUM($L$16:$L$20))*$C$10 -> 0.028531819 | M27: =M9/SQRT(SUM($M$16:$M$20))*$C$11 -> 0.043529455 | N27: =N9/SQRT(SUM($N$16:$N$20))*$C$12 -> 0.015897466 | O27: =O9/SQRT(SUM($O$16:$O$20))*$C$13 -> 0.027353155 | P27: =P9/SQRT(SUM($P$16:$P$20))*$C$14 -> 0.064424412 | Q27: =Q9/SQRT(SUM($Q$16:$Q$20))*$C$15 -> 0.032305647 | R27: =R9/SQRT(SUM($R$16:$R$20))*$C$16 -> 0.0412701
E28: S4 | F28: =(F10/SQRT(SUM($F$16:$F$20)))*$C$4 -> 0.057315628 | G28: =(G10/SQRT(SUM($G$16:$G$20)))*$C$5 -> 0.030049062 | H28: =H10/SQRT(SUM($H$16:$H$20))*$C$6 -> 0.017330461 | I28: =I10/SQRT(SUM($I$16:$I$20))*$C$7 -> 0.013476495 | J28: =J10/SQRT(SUM($J$16:$J$20))*$C$8 -> 0.015944452 | K28: =K10/SQRT(SUM($K$16:$K$20))*$C$9 -> 0.084380278 | L28: =L10/SQRT(SUM($L$16:$L$20))*$C$10 -> 0.028531819 | M28: =M10/SQRT(SUM($M$16:$M$20))*$C$11 -> 0.08705891 | N28: =N10/SQRT(SUM($N$16:$N$20))*$C$12 -> 0.011355333 | O28: =O10/SQRT(SUM($O$16:$O$20))*$C$13 -> 0.038294417 | P28: =P10/SQRT(SUM($P$16:$P$20))*$C$14 -> 0.064424412 | Q28: =Q10/SQRT(SUM($Q$16:$Q$20))*$C$15 -> 0 | R28: =R10/SQRT(SUM($R$16:$R$20))*$C$16 -> 0.0082540199
E29: S5 | F29: =(F11/SQRT(SUM($F$16:$F$20)))*$C$4 -> 0.046894605 | G29: =(G11/SQRT(SUM($G$16:$G$20)))*$C$5 -> 0.032145508 | H29: =H11/SQRT(SUM($H$16:$H$20))*$C$6 -> 0.017330461 | I29: =I11/SQRT(SUM($I$16:$I$20))*$C$7 -> 0.011080673 | J29: =J11/SQRT(SUM($J$16:$J$20))*$C$8 -> 0.015944452 | K29: =K11/SQRT(SUM($K$16:$K$20))*$C$9 -> 0.084380278 | L29: =L11/SQRT(SUM($L$16:$L$20))*$C$10 -> 0.023776516 | M29: =M11/SQRT(SUM($M$16:$M$20))*$C$11 -> 0.043529455 | N29: =N11/SQRT(SUM($N$16:$N$20))*$C$12 -> 0.015897466 | O29: =O11/SQRT(SUM($O$16:$O$20))*$C$13 -> 0.032823786 | P29: =P11/SQRT(SUM($P$16:$P$20))*$C$14 -> 0.046017437 | Q29: =Q11/SQRT(SUM($Q$16:$Q$20))*$C$15 -> 0.021537098 | R29: =R11/SQRT(SUM($R$16:$R$20))*$C$16 -> 0.02476206
E30: A Min | F30: =MIN(F25:F29) -> 0.041684093 | G30: =MIN(G25:G29) -> 0.029350246 | H30: =MIN(H25:H29) -> 0.014179468 | I30: =MIN(I25:I29) -> 0.010481718 | J30: =MIN(J25:J29) -> 0.009566671 | K30: =MIN(K25:K29) -> 0.036162976 | L30: =MIN(L25:L29) -> 0.023776516 | M30: =MIN(M25:M29) -> 0.043529455 | ... R30: =MIN(R25:R29) -> 0.0082540199
E31: A Max | F31: =MAX(F25:F29) -> 0.06252614 | G31: =MAX(G25:G29) -> 0.033543139 | H31: =MAX(H25:H29) -> 0.017330461 | I31: =MAX(I25:I29) -> 0.013476495 | J31: =MAX(J25:J29) -> 0.022322232 | K31: =MAX(K25:K29) -> 0.084380278 | L31: =MAX(L25:L29) -> 0.033287122 | M31: =MAX(M25:M29) -> 0.08705891 | ... R31: =MAX(R25:R29) -> 0.0412701
E33: Tabel Rata-rata Nilai Kriteria Ternormalisasi Terbobot Kuadrat +
E34: Alternatives Supplier | F34: EKONOMI | J34: LINGKUNGAN | M34: SOSIAL | P34: ETIKA | S34: D+
F35: Kualitas | G35: Harga | H35: Delivery | I35: TKDN | J35: Eco-design | K35: Sistem Man. Lingkungan | L35: Green Image | M35: Sistem K3 | N35: CSR | O35: Education & Training | P35: CoC | Q35: CoI | R35: Transparansi Akuntansi Bisnis
E36: S1 | F36: =($F$31-F25)^2 -> 0.00010859773 | G36: =($G$31-G25)^2 -> 4.3950866e-06 | H36: =($H$31-H25)^2 -> 9.9287564e-06 | I36: =($I$31-I25)^2 -> 8.9686866e-06 | J36: =($J$31-J25)^2 -> 0 | K36: =($K$31-K25)^2 -> 0.0023249082 | L36: =($L$31-L25)^2 -> 0 | M36: =($M$31-M25)^2 -> 0 | N36: =($N$31-N25)^2 -> 2.0630973e-05 | O36: =($O$31-O25)^2 -> 0 | P36: =($P$31-P25)^2 -> 8.470418e-05 | Q36: =($Q$31-Q25)^2 -> 0.0010436548 | R36: =($R$31-R25)^2 -> 0.0010900615 | S36: =SQRT(SUM(F36:R36)) -> 0.068526272
E37: S2 | F37: =($F$31-F26)^2 -> 0 | G37: =($G$31-G26)^2 -> 1.7580346e-05 | H37: =($H$31-H26)^2 -> 2.4821891e-06 | I37: =($I$31-I26)^2 -> 2.2421717e-06 | J37: =($J$31-J26)^2 -> 0.00016270435 | K37: =($K$31-K26)^2 -> 0.00058122705 | L37: =($L$31-L26)^2 -> 9.0451632e-05 | M37: =($M$31-M26)^2 -> 0.0018948135 | N37: =($N$31-N26)^2 -> 8.2523892e-05 | O37: =($O$31-O26)^2 -> 0.00026935023 | P37: =($P$31-P26)^2 -> 0.00033881672 | Q37: =($Q$31-Q26)^2 -> 0 | R37: =($R$31-R26)^2 -> 0.00027251538 | S37: =SQRT(SUM(F37:R37)) -> 0.0609484
E38: S3 | F38: =($F$31-F27)^2 -> 0.00043439091 | G38: =($G$31-G27)^2 -> 0 | H38: =($H$31-H27)^2 -> 2.4821891e-06 | I38: =($I$31-I27)^2 -> 4.3946565e-06 | J38: =($J$31-J27)^2 -> 4.0676086e-05 | K38: =($K$31-K27)^2 -> 0.00058122705 | L38: =($L$31-L27)^2 -> 2.2612908e-05 | M38: =($M$31-M27)^2 -> 0.0018948135 | N38: =($N$31-N27)^2 -> 0 | O38: =($O$31-O27)^2 -> 0.00026935023 | P38: =($P$31-P27)^2 -> 0 | Q38: =($Q$31-Q27)^2 -> 0.0004638466 | R38: =($R$31-R27)^2 -> 0 | S38: =SQRT(SUM(F38:R38)) -> 0.060940907
E39: S4 | F39: =($F$31-F28)^2 -> 2.7149432e-05 | G39: =($G$31-G28)^2 -> 1.2208574e-05 | H39: =($H$31-H28)^2 -> 0 | I39: =($I$31-I28)^2 -> 0 | J39: =($J$31-J28)^2 -> 4.0676086e-05 | K39: =($K$31-K28)^2 -> 0 | L39: =($L$31-L28)^2 -> 2.2612908e-05 | M39: =($M$31-M28)^2 -> 0 | N39: =($N$31-N28)^2 -> 2.0630973e-05 | O39: =($O$31-O28)^2 -> 2.9927804e-05 | P39: =($P$31-P28)^2 -> 0 | Q39: =($Q$31-Q28)^2 -> 0.0028990412 | R39: =($R$31-R28)^2 -> 0.0010900615 | S39: =SQRT(SUM(F39:R39)) -> 0.064360769
E40: S5 | F40: =($F$31-F29)^2 -> 0.00024434489 | G40: =($G$31-G29)^2 -> 1.9533718e-06 | H40: =($H$31-H29)^2 -> 0 | I40: =($I$30-I29)^2 -> 3.5874747e-07 | J40: =($J$30-J29)^2 -> 4.0676086e-05 | K40: =($K$30-K29)^2 -> 0.0023249082 | L40: =($L$30-L29)^2 -> 0 | M40: =($M$30-M29)^2 -> 0 | N40: =($N$30-N29)^2 -> 8.2523892e-05 | O40: =($O$30-O29)^2 -> 2.9927804e-05 | P40: =($P$30-P29)^2 -> 0 | Q40: =($Q$30-Q29)^2 -> 0.0004638466 | R40: =($R$30-R29)^2 -> 0.00027251538 | S40: =SQRT(SUM(F40:R40)) -> 0.058830731
E42: Tabel Rata-rata Nilai Kriteria Ternormalisasi Terbobot Kuadrat -
E43: Alternatives Supplier | F43: EKONOMI | J43: LINGKUNGAN | M43: SOSIAL | P43: ETIKA | S43: D-
F44: Kualitas | G44: Harga | H44: Delivery | I44: TKDN | J44: Eco-design | K44: Sistem Man. Lingkungan | L44: Green Image | M44: Sistem K3 | N44: CSR | O44: Education & Training | P44: CoC | Q44: CoI | R44: Transparansi Akuntansi Bisnis
...

Sheet AHP-Topsis cek
A1: Tabel Nilai Sub Kriteria
A3: Kriteria | B3: Sub Kriteria | E3: Tabel Alternatif dan Sub Kriteria
A4: Ekonomi C01 | B4: Kualitas | C4: ='AHP edit'!M53/4 -> 0.11766992 | E4: Alternatives Supplier | F4: EKONOMI | J4: LINGKUNGAN | M4: SOSIAL | P4: ETIKA
B5: Harga | C5: ='AHP edit'!M54/4 -> 0.070083903 | F5: Kualitas | G5: Harga | H5: Delivery | I5: TKDN | J5: Eco-design | K5: Sistem Man. Lingkungan | L5: Green Image | M5: Sistem K3 | N5: CSR | O5: Education & Training | P5: CoC | Q5: CoI | R5: Transparansi Akuntansi Bisnis
B6: Pengiriman | C6: ='AHP edit'!M55/4 -> 0.036030333 | F6: DPMO | G6: USD | H6: Days | I6: % | J6: High-Low (Rating 0-7) | K6: High-Low (Rating 0-7) | L6: High-Low (Rating 0-7) | M6: Lost Time Injury Freq. Rate | N6: High-Low (Rating 0-7) | O6: No. of Training Sessions | P6: High-Low (Rating 0-7) | Q6: No. of Cases | R6: Disclosure level
B7: TKDN | C7: ='AHP edit'!M56/4 -> 0.026215844 | E7: S1 | F7: 200 | G7: 4500000 | H7: 180 | I7: 35 | J7: 7 | K7: 3 | L7: 7 | M7: 2 | N7: 5 | O7: 8 | P7: 6 | Q7: 2 | R7: 1
A8: Lingkungan C02 | B8: Eco-Design | C8: ='AHP edit'!K80/4 -> 0.036776077 | E8: S2 | F8: 240 | G8: 4200000 | H8: 200 | I8: 40 | J8: 3 | K8: 5 | L8: 5 | M8: 1 | N8: 3 | O8: 5 | P8: 5 | Q8: 5 | R8: 3
B9: SML | C9: ='AHP edit'!K81/4 -> 0.15104027 | E9: S3 | F9: 160 | G9: 4800000 | H9: 200 | I9: 38 | J9: 5 | K9: 5 | L9: 6 | M9: 1 | N9: 7 | O9: 5 | P9: 7 | Q9: 3 | R9: 5
B10: Green Image | C10: ='AHP edit'!K82/4 -> 0.062183657 | E10: S4 | F10: 220 | G10: 4300000 | H10: 220 | I10: 45 | J10: 5 | K10: 7 | L10: 6 | M10: 2 | N10: 5 | O10: 7 | P10: 7 | Q10: 0 | R10: 1
A11: Sosial C03 | B11: SKK | C11: ='AHP edit'!K105/4 -> 0.14437087 | E11: S5 | F11: 180 | G11: 4600000 | H11: 220 | I11: 37 | J11: 5 | K11: 7 | L11: 5 | M11: 1 | N11: 7 | O11: 6 | P11: 5 | Q11: 2 | R11: 3
B12: CSR | C12: ='AHP edit'!K106/4 -> 0.028456382
B13: ET | C13: ='AHP edit'!K107/4 -> 0.077172748 | E13: Tabel Alternatif dan Sub Kriteria Kuadrat
A14: Etika C04 | B14: CoC | C14: ='AHP edit'!K130/4 -> 0.12484218 | E14: Alternatives Supplier | F14: EKONOMI | J14: LINGKUNGAN | M14: SOSIAL | P14: ETIKA
B15: Col | C15: ='AHP edit'!K131/4 -> 0.069788174 | F15: Kualitas | G15: Harga | H15: Delivery | I15: TKDN | J15: Eco-design | K15: Sistem Man. Lingkungan | L15: Green Image | M15: Sistem K3 | N15: CSR | O15: Education & Training | P15: CoC | Q15: CoI | R15: Transparansi Akuntansi Bisnis
B16: TAB | C16: ='AHP edit'!K132/4 -> 0.055369649 | E16: S1 | F16: =F7^2 -> 40000 | G16: =G7^2 -> 20250000000000 | H16: =H7^2 -> 32400 | I16: =I7^2 -> 1225 | J16: =J7^2 -> 49 | K16: =K7^2 -> 9 | L16: =L7^2 -> 49 | M16: =M7^2 -> 4 | ... R16: =R7^2 -> 1
E17: S2 | F17: =F8^2 -> 57600 | G17: =G8^2 -> 17640000000000 | H17: =H8^2 -> 40000 | I17: =I8^2 -> 1600 | J17: =J8^2 -> 9 | K17: =K8^2 -> 25 | L17: =L8^2 -> 25 | M17: =M8^2 -> 1 | ... R17: =R8^2 -> 9
E18: S3 | F18: =F9^2 -> 25600 | G18: =G9^2 -> 23040000000000 | H18: =H9^2 -> 40000 | I18: =I9^2 -> 1444 | J18: =J9^2 -> 25 | K18: =K9^2 -> 25 | L18: =L9^2 -> 36 | M18: =M9^2 -> 1 | ... R18: =R9^2 -> 25
E19: S4 | F19: =F10^2 -> 48400 | G19: =G10^2 -> 18490000000000 | H19: =H10^2 -> 48400 | I19: =I10^2 -> 2025 | J19: =J10^2 -> 25 | K19: =K10^2 -> 49 | L19: =L10^2 -> 36 | M19: =M10^2 -> 4 | ... R19: =R10^2 -> 1
E20: S5 | F20: =F11^2 -> 32400 | G20: =G11^2 -> 21160000000000 | H20: =H11^2 -> 48400 | I20: =I11^2 -> 1369 | J20: =J11^2 -> 25 | K20: =K11^2 -> 49 | L20: =L11^2 -> 25 | M20: =M11^2 -> 1 | ... R20: =R11^2 -> 9
E22: Tabel Rata-rata Nilai Kriteria Ternormalisasi Terbobot
E23: Alternatives Supplier | F23: EKONOMI | J23: LINGKUNGAN | M23: SOSIAL | P23: ETIKA
F24: Kualitas | G24: Harga | H24: Delivery | I24: TKDN | J24: Eco-design | K24: Sistem Man. Lingkungan | L24: Green Image | M24: Sistem K3 | N24: CSR | O24: Education & Training | P24: CoC | Q24: CoI | R24: Transparansi Akuntansi Bisnis
E25: S1 | F25: =(F7/SQRT(SUM($F$16:$F$20)))*$C$4 -> 0.052105117 | G25: =(G7/SQRT(SUM($G$16:$G$20)))*$C$5 -> 0.031446693 | H25: =H7/SQRT(SUM($H$16:$H$20))*$C$6 -> 0.014179468 | I25: =I7/SQRT(SUM($I$16:$I$20))*$C$7 -> 0.010481718 | J25: =J7/SQRT(SUM($J$16:$J$20))*$C$8 -> 0.022322232 | K25: =K7/SQRT(SUM($K$16:$K$20))*$C$9 -> 0.036162976 | L25: =L7/SQRT(SUM($L$16:$L$20))*$C$10 -> 0.033287122 | M25: =M7/SQRT(SUM($M$16:$M$20))*$C$11 -> 0.08705891 | N25: =N7/SQRT(SUM($N$16:$N$20))*$C$12 -> 0.011355333 | O25: =O7/SQRT(SUM($O$16:$O$20))*$C$13 -> 0.043765048 | P25: =P7/SQRT(SUM($P$16:$P$20))*$C$14 -> 0.055220924 | Q25: =Q7/SQRT(SUM($Q$16:$Q$20))*$C$15 -> 0.021537098 | R25: =R7/SQRT(SUM($R$16:$R$20))*$C$16 -> 0.0082540199
E26: S2 | F26: =(F8/SQRT(SUM($F$16:$F$20)))*$C$4 -> 0.06252614 | G26: =(G8/SQRT(SUM($G$16:$G$20)))*$C$5 -> 0.029350246 | H26: =H8/SQRT(SUM($H$16:$H$20))*$C$6 -> 0.015754965 | I26: =I8/SQRT(SUM($I$16:$I$20))*$C$7 -> 0.011979106 | J26: =J8/SQRT(SUM($J$16:$J$20))*$C$8 -> 0.009566671 | K26: =K8/SQRT(SUM($K$16:$K$20))*$C$9 -> 0.060271627 | L26: =L8/SQRT(SUM($L$16:$L$20))*$C$10 -> 0.023776516 | M26: =M8/SQRT(SUM($M$16:$M$20))*$C$11 -> 0.043529455 | N26: =N8/SQRT(SUM($N$16:$N$20))*$C$12 -> 0.0068131996 | O26: =O8/SQRT(SUM($O$16:$O$20))*$C$13 -> 0.027353155 | P26: =P8/SQRT(SUM($P$16:$P$20))*$C$14 -> 0.046017437 | Q26: =Q8/SQRT(SUM($Q$16:$Q$20))*$C$15 -> 0.053842745 | R26: =R8/SQRT(SUM($R$16:$R$20))*$C$16 -> 0.02476206
E27: S3 | F27: =(F9/SQRT(SUM($F$16:$F$20)))*$C$4 -> 0.041684093 | G27: =(G9/SQRT(SUM($G$16:$G$20)))*$C$5 -> 0.033543139 | H27: =H9/SQRT(SUM($H$16:$H$20))*$C$6 -> 0.015754965 | I27: =I9/SQRT(SUM($I$16:$I$20))*$C$7 -> 0.011380151 | J27: =J9/SQRT(SUM($J$16:$J$20))*$C$8 -> 0.015944452 | K27: =K9/SQRT(SUM($K$16:$K$20))*$C$9 -> 0.060271627 | L27: =L9/SQRT(SUM($L$16:$L$20))*$C$10 -> 0.028531819 | M27: =M9/SQRT(SUM($M$16:$M$20))*$C$11 -> 0.043529455 | N27: =N9/SQRT(SUM($N$16:$N$20))*$C$12 -> 0.015897466 | O27: =O9/SQRT(SUM($O$16:$O$20))*$C$13 -> 0.027353155 | P27: =P9/SQRT(SUM($P$16:$P$20))*$C$14 -> 0.064424412 | Q27: =Q9/SQRT(SUM($Q$16:$Q$20))*$C$15 -> 0.032305647 | R27: =R9/SQRT(SUM($R$16:$R$20))*$C$16 -> 0.0412701
E28: S4 | F28: =(F10/SQRT(SUM($F$16:$F$20)))*$C$4 -> 0.057315628 | G28: =(G10/SQRT(SUM($G$16:$G$20)))*$C$5 -> 0.030049062 | H28: =H10/SQRT(SUM($H$16:$H$20))*$C$6 -> 0.017330461 | I28: =I10/SQRT(SUM($I$16:$I$20))*$C$7 -> 0.013476495 | J28: =J10/SQRT(SUM($J$16:$J$20))*$C$8 -> 0.015944452 | K28: =K10/SQRT(SUM($K$16:$K$20))*$C$9 -> 0.084380278 | L28: =L10/SQRT(SUM($L$16:$L$20))*$C$10 -> 0.028531819 | M28: =M10/SQRT(SUM($M$16:$M$20))*$C$11 -> 0.08705891 | N28: =N10/SQRT(SUM($N$16:$N$20))*$C$12 -> 0.011355333 | O28: =O10/SQRT(SUM($O$16:$O$20))*$C$13 -> 0.038294417 | P28: =P10/SQRT(SUM($P$16:$P$20))*$C$14 -> 0.064424412 | Q28: =Q10/SQRT(SUM($Q$16:$Q$20))*$C$15 -> 0 | R28: =R10/SQRT(SUM($R$16:$R$20))*$C$16 -> 0.0082540199
E29: S5 | F29: =(F11/SQRT(SUM($F$16:$F$20)))*$C$4 -> 0.046894605 | G29: =(G11/SQRT(SUM($G$16:$G$20)))*$C$5 -> 0.032145508 | H29: =H11/SQRT(SUM($H$16:$H$20))*$C$6 -> 0.017330461 | I29: =I11/SQRT(SUM($I$16:$I$20))*$C$7 -> 0.011080673 | J29: =J11/SQRT(SUM($J$16:$J$20))*$C$8 -> 0.015944452 | K29: =K11/SQRT(SUM($K$16:$K$20))*$C$9 -> 0.084380278 | L29: =L11/SQRT(SUM($L$16:$L$20))*$C$10 -> 0.023776516 | M29: =M11/SQRT(SUM($M$16:$M$20))*$C$11 -> 0.043529455 | N29: =N11/SQRT(SUM($N$16:$N$20))*$C$12 -> 0.015897466 | O29: =O11/SQRT(SUM($O$16:$O$20))*$C$13 -> 0.032823786 | P29: =P11/SQRT(SUM($P$16:$P$20))*$C$14 -> 0.046017437 | Q29: =Q11/SQRT(SUM($Q$16:$Q$20))*$C$15 -> 0.021537098 | R29: =R11/SQRT(SUM($R$16:$R$20))*$C$16 -> 0.02476206
E30: A Max | F30: =MAX(F24:F28) -> 0.06252614 | G30: =MAX(G24:G28) -> 0.033543139 | H30: =MAX(H24:H28) -> 0.017330461 | I30: =MAX(I24:I28) -> 0.013476495 | J30: =MAX(J24:J28) -> 0.022322232 | K30: =MAX(K24:K28) -> 0.084380278 | L30: =MAX(L24:L28) -> 0.033287122 | M30: =MAX(M24:M28) -> 0.08705891 | ... R30: =MAX(R24:R28) -> 0.0412701
E31: A Min | F31: =MIN(F25:F29) -> 0.041684093 | G31: =MIN(G25:G29) -> 0.029350246 | H31: =MIN(H25:H29) -> 0.014179468 | I31: =MIN(I25:I29) -> 0.010481718 | J31: =MIN(J25:J29) -> 0.009566671 | K31: =MIN(K25:K29) -> 0.036162976 | L31: =MIN(L25:L29) -> 0.023776516 | M31: =MIN(M25:M29) -> 0.043529455 | ... R31: =MIN(R25:R29) -> 0.0082540199
E33: A+ | F33: min | G33: min | H33: min | I33: max | J33: max | K33: max | L33: max | M33: min | N33: max | O33: max | P33: max | Q33: min | R33: max
E34: A- | F34: max | G34: max | H34: max | I34: min | J34: min | K34: min | L34: min | M34: max | N34: min | O34: min | P34: min | Q34: max | R34: min
E37: Tabel Rata-rata Nilai Kriteria Ternormalisasi Terbobot Kuadrat +
E38: Alternatives Supplier | F38: EKONOMI | J38: LINGKUNGAN | M38: SOSIAL | P38: ETIKA | S38: D+
F39: Kualitas | G39: Harga | H39: Delivery | I39: TKDN | J39: Eco-design | K39: Sistem Man. Lingkungan | L39: Green Image | M39: Sistem K3 | N39: CSR | O39: Education & Training | P39: CoC | Q39: CoI | R39: Transparansi Akuntansi Bisnis
E40: S1 | F40: =($F$30-F25)^2 -> 0.00010859773 | G40: =($G$30-G25)^2 -> 4.3950866e-06 | H40: =($H$30-H25)^2 -> 9.9287564e-06 | I40: =($I$30-I25)^2 -> 8.9686866e-06 | J40: =($J$30-J25)^2 -> 0 | K40: =($K$30-K25)^2 -> 0.0023249082 | L40: =($L$30-L25)^2 -> 0 | M40: =($M$30-M25)^2 -> 0 | N40: =($N$30-N25)^2 -> 2.0630973e-05 | O40: =($O$30-O25)^2 -> 0 | P40: =($P$30-P25)^2 -> 8.470418e-05 | Q40: =($Q$30-Q25)^2 -> 0.0010436548 | R40: =($R$30-R25)^2 -> 0.0010900615 | S40: =SQRT(SUM(F40:R40)) -> 0.068526272
E41: S2 | F41: =($F$30-F26)^2 -> 0 | G41: =($G$30-G26)^2 -> 1.7580346e-05 | H41: =($H$30-H26)^2 -> 2.4821891e-06 | I41: =($I$30-I26)^2 -> 2.2421717e-06 | J41: =($J$30-J26)^2 -> 0.00016270435 | K41: =($K$30-K26)^2 -> 0.00058122705 | L41: =($L$30-L26)^2 -> 9.0451632e-05 | M41: =($M$30-M26)^2 -> 0.0018948135 | N41: =($N$30-N26)^2 -> 8.2523892e-05 | O41: =($O$30-O26)^2 -> 0.00026935023 | P41: =($P$30-P26)^2 -> 0.00033881672 | Q41: =($Q$30-Q26)^2 -> 0 | R41: =($R$30-R26)^2 -> 0.00027251538 | S41: =SQRT(SUM(F41:R41)) -> 0.0609484
E42: S3 | F42: =($F$30-F27)^2 -> 0.00043439091 | G42: =($G$30-G27)^2 -> 0 | H42: =($H$30-H27)^2 -> 2.4821891e-06 | I42: =($I$30-I27)^2 -> 4.3946565e-06 | J42: =($J$30-J27)^2 -> 4.0676086e-05 | K42: =($K$30-K27)^2 -> 0.00058122705 | L42: =($L$30-L27)^2 -> 2.2612908e-05 | M42: =($M$30-M27)^2 -> 0.0018948135 | N42: =($N$30-N27)^2 -> 0 | O42: =($O$30-O27)^2 -> 0.00026935023 | P42: =($P$30-P27)^2 -> 0 | Q42: =($Q$30-Q27)^2 -> 0.0004638466 | R42: =($R$30-R27)^2 -> 0 | S42: =SQRT(SUM(F42:R42)) -> 0.060940907
E43: S4 | F43: =($F$30-F28)^2 -> 2.7149432e-05 | G43: =($G$30-G28)^2 -> 1.2208574e-05 | H43: =($H$30-H28)^2 -> 0 | I43: =($I$30-I28)^2 -> 0 | J43: =($J$30-J28)^2 -> 4.0676086e-05 | K43: =($K$30-K28)^2 -> 0 | L43: =($L$30-L28)^2 -> 2.2612908e-05 | M43: =($M$30-M28)^2 -> 0 | N43: =($N$30-N28)^2 -> 2.0630973e-05 | O43: =($O$30-O28)^2 -> 2.9927804e-05 | P43: =($P$30-P28)^2 -> 0 | Q43: =($Q$30-Q28)^2 -> 0.0028990412 | R43: =($R$30-R28)^2 -> 0.0010900615 | S43: =SQRT(SUM(F43:R43)) -> 0.064360769
E44: S5 | F44: =($F$30-F29)^2 -> 0.00024434489 | G44: =($G$30-G29)^2 -> 1.9533718e-06 | H44: =($H$30-H29)^2 -> 0 | I44: =($I$30-I29)^2 -> 5.7399594e-06 | J44: =($J$30-J29)^2 -> 4.0676086e-05 | K44: =($K$30-K29)^2 -> 0 | L44: =($L$30-L29)^2 -> 9.0451632e-05 | M44: =($M$30-M29)^2 -> 0.0018948135 | N44: =($N$30-N29)^2 -> 0 | O44: =($O$30-O29)^2 -> 0.00011971122 | P44: =($P$30-P29)^2 -> 0.00033881672 | Q44: =($Q$30-Q29)^2 -> 0.0010436548 | R44: =($R$30-R29)^2 -> 0.00027251538 | S44: =SQRT(SUM(F44:R44)) -> 0.063660644
E46: Tabel Rata-rata Nilai Kriteria Ternormalisasi Terbobot Kuadrat -
...

Sheet AHP-Topsis cek tugas
A1: Tabel Nilai Sub Kriteria
A3: Kriteria | B3: Sub Kriteria | C3: Bobot | E3: Tabel Alternatif dan Sub Kriteria
A4: Ekonomi | B4: Kualitas | C4: ='AHP edit'!M53/4 -> 0.11766992 | E4: Alternatives Supplier | F4: EKONOMI | J4: LINGKUNGAN | M4: SOSIAL | P4: ETIKA
B5: Harga | C5: ='AHP edit'!M54/4 -> 0.070083903 | F5: Kualitas | G5: Harga | H5: Delivery | I5: TKDN | J5: Eco-design | K5: Sistem Man. Lingkungan | L5: Green Image | M5: Sistem K3 | N5: CSR | O5: Education & Training | P5: CoC | Q5: CoI | R5: Transparansi Akuntansi Bisnis
B6: Pengiriman | C6: ='AHP edit'!M55/4 -> 0.036030333 | F6: DPMO | G6: USD | H6: Days | I6: % | J6: High-Low (Rating 0-7) | K6: High-Low (Rating 0-7) | L6: High-Low (Rating 0-7) | M6: Lost Time Injury Freq. Rate | N6: High-Low (Rating 0-7) | O6: No. of Training Sessions | P6: High-Low (Rating 0-7) | Q6: No. of Cases | R6: Disclosure level
B7: TKDN | C7: ='AHP edit'!M56/4 -> 0.026215844 | E7: S1 | F7: 200 | G7: 4500000 | H7: 180 | I7: 35 | J7: 7 | K7: 3 | L7: 7 | M7: 2 | N7: 5 | O7: 8 | P7: 6 | Q7: 2 | R7: 1
A8: Lingkungan | B8: Eco-Design | C8: ='AHP edit'!K80/4 -> 0.036776077 | E8: S2 | F8: 240 | G8: 4200000 | H8: 200 | I8: 40 | J8: 3 | K8: 5 | L8: 5 | M8: 1 | N8: 3 | O8: 5 | P8: 5 | Q8: 5 | R8: 3
B9: SML | C9: ='AHP edit'!K81/4 -> 0.15104027 | E9: S3 | F9: 160 | G9: 4800000 | H9: 200 | I9: 38 | J9: 5 | K9: 5 | L9: 6 | M9: 1 | N9: 7 | O9: 5 | P9: 7 | Q9: 3 | R9: 5
B10: Green Image | C10: ='AHP edit'!K82/4 -> 0.062183657 | E10: S4 | F10: 220 | G10: 4300000 | H10: 220 | I10: 45 | J10: 5 | K10: 7 | L10: 6 | M10: 2 | N10: 5 | O10: 7 | P10: 7 | Q10: 0 | R10: 1
A11: Sosial | B11: SKK | C11: ='AHP edit'!K105/4 -> 0.14437087 | E11: S5 | F11: 180 | G11: 4600000 | H11: 220 | I11: 37 | J11: 5 | K11: 7 | L11: 5 | M11: 1 | N11: 7 | O11: 6 | P11: 5 | Q11: 2 | R11: 3
B12: CSR | C12: ='AHP edit'!K106/4 -> 0.028456382
B13: ET | C13: ='AHP edit'!K107/4 -> 0.077172748 | E13: Tabel Alternatif dan Sub Kriteria Kuadrat
A14: Etika | B14: CoC | C14: ='AHP edit'!K130/4 -> 0.12484218 | E14: Alternatives Supplier | F14: EKONOMI | J14: LINGKUNGAN | M14: SOSIAL | P14: ETIKA
B15: Col | C15: ='AHP edit'!K131/4 -> 0.069788174 | F15: Kualitas | G15: Harga | H15: Delivery | I15: TKDN | J15: Eco-design | K15: Sistem Man. Lingkungan | L15: Green Image | M15: Sistem K3 | N15: CSR | O15: Education & Training | P15: CoC | Q15: CoI | R15: Transparansi Akuntansi Bisnis | T15: Tabel Rata-rata Nilai Kriteria Ternormalisasi
B16: TAB | C16: ='AHP edit'!K132/4 -> 0.055369649 | E16: S1 | F16: =F7^2 -> 40000 | G16: =G7^2 -> 20250000000000 | H16: =H7^2 -> 32400 | I16: =I7^2 -> 1225 | J16: =J7^2 -> 49 | K16: =K7^2 -> 9 | L16: =L7^2 -> 49 | M16: =M7^2 -> 4 | ... R16: =R7^2 -> 1 | T16: Alternatives Supplier | U16: EKONOMI | Y16: LINGKUNGAN | AB16: SOSIAL | AE16: ETIKA
B17: Total | C17: =SUM(C4:C16) -> 1 | E17: S2 | F17: =F8^2 -> 57600 | G17: =G8^2 -> 17640000000000 | H17: =H8^2 -> 40000 | I17: =I8^2 -> 1600 | J17: =J8^2 -> 9 | K17: =K8^2 -> 25 | L17: =L8^2 -> 25 | M17: =M8^2 -> 1 | ... R17: =R8^2 -> 9 | U17: Kualitas | V17: Harga | W17: Delivery | X17: TKDN | Y17: Eco-design | Z17: Sistem Man. Lingkungan | AA17: Green Image | AB17: Sistem K3 | AC17: CSR | AD17: Education & Training | AE17: CoC | AF17: CoI | AG17: Transparansi Akuntansi Bisnis
E18: S3 | F18: =F9^2 -> 25600 | G18: =G9^2 -> 23040000000000 | H18: =H9^2 -> 40000 | I18: =I9^2 -> 1444 | J18: =J9^2 -> 25 | K18: =K9^2 -> 25 | L18: =L9^2 -> 36 | M18: =M9^2 -> 1 | ... R18: =R9^2 -> 25 | T18: S1 | U18: =(F7/SQRT(SUM($F$16:$F$20))) -> 0.44280744 | V18: =(G7/SQRT(SUM($G$16:$G$20))) -> 0.44870065 | W18: =(H7/SQRT(SUM($H$16:$H$20))) -> 0.39354252 | X18: =(I7/SQRT(SUM($I$16:$I$20))) -> 0.39982379 | Y18: =(J7/SQRT(SUM($J$16:$J$20))) -> 0.60697698 | Z18: =(K7/SQRT(SUM($K$16:$K$20))) -> 0.23942607 | AA18: =(L7/SQRT(SUM($L$16:$L$20))) -> 0.53530338 | AB18: =(M7/SQRT(SUM($M$16:$M$20))) -> 0.60302269 | AC18: =(N7/SQRT(SUM($N$16:$N$20))) -> 0.39904344 | AD18: =(O7/SQRT(SUM($O$16:$O$20))) -> 0.56710496 | AE18: =(P7/SQRT(SUM($P$16:$P$20))) -> 0.44232587 | AF18: =(Q7/SQRT(SUM($Q$16:$Q$20))) -> 0.3086067 | AG18: =(R7/SQRT(SUM($R$16:$R$20))) -> 0.1490712
E19: S4 | F19: =F10^2 -> 48400 | G19: =G10^2 -> 18490000000000 | H19: =H10^2 -> 48400 | I19: =I10^2 -> 2025 | J19: =J10^2 -> 25 | K19: =K10^2 -> 49 | L19: =L10^2 -> 36 | M19: =M10^2 -> 4 | ... R19: =R10^2 -> 1 | T19: S2 | U19: =(F8/SQRT(SUM($F$16:$F$20))) -> 0.53136893 | V19: =(G8/SQRT(SUM($G$16:$G$20))) -> 0.41878727 | W19: =(H8/SQRT(SUM($H$16:$H$20))) -> 0.43726947 | X19: =(I8/SQRT(SUM($I$16:$I$20))) -> 0.45694147 | Y19: =(J8/SQRT(SUM($J$16:$J$20))) -> 0.26013299 | Z19: =(K8/SQRT(SUM($K$16:$K$20))) -> 0.39904344 | AA19: =(L8/SQRT(SUM($L$16:$L$20))) -> 0.38235956 | AB19: =(M8/SQRT(SUM($M$16:$M$20))) -> 0.30151134 | AC19: =(N8/SQRT(SUM($N$16:$N$20))) -> 0.23942607 | AD19: =(O8/SQRT(SUM($O$16:$O$20))) -> 0.3544406 | AE19: =(P8/SQRT(SUM($P$16:$P$20))) -> 0.36860489 | AF19: =(Q8/SQRT(SUM($Q$16:$Q$20))) -> 0.77151675 | AG19: =(R8/SQRT(SUM($R$16:$R$20))) -> 0.4472136
E20: S5 | F20: =F11^2 -> 32400 | G20: =G11^2 -> 21160000000000 | H20: =H11^2 -> 48400 | I20: =I11^2 -> 1369 | J20: =J11^2 -> 25 | K20: =K11^2 -> 49 | L20: =L11^2 -> 25 | M20: =M11^2 -> 1 | ... R20: =R11^2 -> 9 | T20: S3 | U20: =(F9/SQRT(SUM($F$16:$F$20))) -> 0.35424595 | V20: =(G9/SQRT(SUM($G$16:$G$20))) -> 0.47861403 | W20: =(H9/SQRT(SUM($H$16:$H$20))) -> 0.43726947 | X20: =(I9/SQRT(SUM($I$16:$I$20))) -> 0.4340944 | Y20: =(J9/SQRT(SUM($J$16:$J$20))) -> 0.43355498 | Z20: =(K9/SQRT(SUM($K$16:$K$20))) -> 0.39904344 | AA20: =(L9/SQRT(SUM($L$16:$L$20))) -> 0.45883147 | AB20: =(M9/SQRT(SUM($M$16:$M$20))) -> 0.30151134 | AC20: =(N9/SQRT(SUM($N$16:$N$20))) -> 0.55866082 | AD20: =(O9/SQRT(SUM($O$16:$O$20))) -> 0.3544406 | AE20: =(P9/SQRT(SUM($P$16:$P$20))) -> 0.51604685 | AF20: =(Q9/SQRT(SUM($Q$16:$Q$20))) -> 0.46291005 | AG20: =(R9/SQRT(SUM($R$16:$R$20))) -> 0.74535599
T21: S4 | U21: =(F10/SQRT(SUM($F$16:$F$20))) -> 0.48708819 | V21: =(G10/SQRT(SUM($G$16:$G$20))) -> 0.4287584 | W21: =(H10/SQRT(SUM($H$16:$H$20))) -> 0.48099642 | X21: =(I10/SQRT(SUM($I$16:$I$20))) -> 0.51405916 | Y21: =(J10/SQRT(SUM($J$16:$J$20))) -> 0.43355498 | Z21: =(K10/SQRT(SUM($K$16:$K$20))) -> 0.55866082 | AA21: =(L10/SQRT(SUM($L$16:$L$20))) -> 0.45883147 | AB21: =(M10/SQRT(SUM($M$16:$M$20))) -> 0.60302269 | AC21: =(N10/SQRT(SUM($N$16:$N$20))) -> 0.39904344 | AD21: =(O10/SQRT(SUM($O$16:$O$20))) -> 0.49621684 | AE21: =(P10/SQRT(SUM($P$16:$P$20))) -> 0.51604685 | AF21: =(Q10/SQRT(SUM($Q$16:$Q$20))) -> 0 | AG21: =(R10/SQRT(SUM($R$16:$R$20))) -> 0.1490712
E22: Tabel Rata-rata Nilai Kriteria Ternormalisasi Terbobot | T22: S5 | U22: =(F11/SQRT(SUM($F$16:$F$20))) -> 0.3985267 | V22: =(G11/SQRT(SUM($G$16:$G$20))) -> 0.45867177 | W22: =(H11/SQRT(SUM($H$16:$H$20))) -> 0.48099642 | X22: =(I11/SQRT(SUM($I$16:$I$20))) -> 0.42267086 | Y22: =(J11/SQRT(SUM($J$16:$J$20))) -> 0.43355498 | Z22: =(K11/SQRT(SUM($K$16:$K$20))) -> 0.55866082 | AA22: =(L11/SQRT(SUM($L$16:$L$20))) -> 0.38235956 | AB22: =(M11/SQRT(SUM($M$16:$M$20))) -> 0.30151134 | AC22: =(N11/SQRT(SUM($N$16:$N$20))) -> 0.55866082 | AD22: =(O11/SQRT(SUM($O$16:$O$20))) -> 0.42532872 | AE22: =(P11/SQRT(SUM($P$16:$P$20))) -> 0.36860489 | AF22: =(Q11/SQRT(SUM($Q$16:$Q$20))) -> 0.3086067 | AG22: =(R11/SQRT(SUM($R$16:$R$20))) -> 0.4472136
E23: Alternatives Supplier | F23: EKONOMI | J23: LINGKUNGAN | M23: SOSIAL | P23: ETIKA
F24: Kualitas | G24: Harga | H24: Delivery | I24: TKDN | J24: Eco-design | K24: Sistem Man. Lingkungan | L24: Green Image | M24: Sistem K3 | N24: CSR | O24: Education & Training | P24: CoC | Q24: CoI | R24: Transparansi Akuntansi Bisnis
E25: S1 | F25: =(F7/SQRT(SUM($F$16:$F$20)))*$C$4 -> 0.052105117 | G25: =(G7/SQRT(SUM($G$16:$G$20)))*$C$5 -> 0.031446693 | H25: =H7/SQRT(SUM($H$16:$H$20))*$C$6 -> 0.014179468 | I25: =I7/SQRT(SUM($I$16:$I$20))*$C$7 -> 0.010481718 | J25: =J7/SQRT(SUM($J$16:$J$20))*$C$8 -> 0.022322232 | K25: =K7/SQRT(SUM($K$16:$K$20))*$C$9 -> 0.036162976 | L25: =L7/SQRT(SUM($L$16:$L$20))*$C$10 -> 0.033287122 | M25: =M7/SQRT(SUM($M$16:$M$20))*$C$11 -> 0.08705891 | N25: =N7/SQRT(SUM($N$16:$N$20))*$C$12 -> 0.011355333 | O25: =O7/SQRT(SUM($O$16:$O$20))*$C$13 -> 0.043765048 | P25: =P7/SQRT(SUM($P$16:$P$20))*$C$14 -> 0.055220924 | Q25: =Q7/SQRT(SUM($Q$16:$Q$20))*$C$15 -> 0.021537098 | R25: =R7/SQRT(SUM($R$16:$R$20))*$C$16 -> 0.0082540199
E26: S2 | F26: =(F8/SQRT(SUM($F$16:$F$20)))*$C$4 -> 0.06252614 | G26: =(G8/SQRT(SUM($G$16:$G$20)))*$C$5 -> 0.029350246 | H26: =H8/SQRT(SUM($H$16:$H$20))*$C$6 -> 0.015754965 | I26: =I8/SQRT(SUM($I$16:$I$20))*$C$7 -> 0.011979106 | J26: =J8/SQRT(SUM($J$16:$J$20))*$C$8 -> 0.009566671 | K26: =K8/SQRT(SUM($K$16:$K$20))*$C$9 -> 0.060271627 | L26: =L8/SQRT(SUM($L$16:$L$20))*$C$10 -> 0.023776516 | M26: =M8/SQRT(SUM($M$16:$M$20))*$C$11 -> 0.043529455 | N26: =N8/SQRT(SUM($N$16:$N$20))*$C$12 -> 0.0068131996 | O26: =O8/SQRT(SUM($O$16:$O$20))*$C$13 -> 0.027353155 | P26: =P8/SQRT(SUM($P$16:$P$20))*$C$14 -> 0.046017437 | Q26: =Q8/SQRT(SUM($Q$16:$Q$20))*$C$15 -> 0.053842745 | R26: =R8/SQRT(SUM($R$16:$R$20))*$C$16 -> 0.02476206
E27: S3 | F27: =(F9/SQRT(SUM($F$16:$F$20)))*$C$4 -> 0.041684093 | G27: =(G9/SQRT(SUM($G$16:$G$20)))*$C$5 -> 0.033543139 | H27: =H9/SQRT(SUM($H$16:$H$20))*$C$6 -> 0.015754965 | I27: =I9/SQRT(SUM($I$16:$I$20))*$C$7 -> 0.011380151 | J27: =J9/SQRT(SUM($J$16:$J$20))*$C$8 -> 0.015944452 | K27: =K9/SQRT(SUM($K$16:$K$20))*$C$9 -> 0.060271627 | L27: =L9/SQRT(SUM($L$16:$L$20))*$C$10 -> 0.028531819 | M27: =M9/SQRT(SUM($M$16:$M$20))*$C$11 -> 0.043529455 | N27: =N9/SQRT(SUM($N$16:$N$20))*$C$12 -> 0.015897466 | O27: =O9/SQRT(SUM($O$16:$O$20))*$C$13 -> 0.027353155 | P27: =P9/SQRT(SUM($P$16:$P$20))*$C$14 -> 0.064424412 | Q27: =Q9/SQRT(SUM($Q$16:$Q$20))*$C$15 -> 0.032305647 | R27: =R9/SQRT(SUM($R$16:$R$20))*$C$16 -> 0.0412701
E28: S4 | F28: =(F10/SQRT(SUM($F$16:$F$20)))*$C$4 -> 0.057315628 | G28: =(G10/SQRT(SUM($G$16:$G$20)))*$C$5 -> 0.030049062 | H28: =H10/SQRT(SUM($H$16:$H$20))*$C$6 -> 0.017330461 | I28: =I10/SQRT(SUM($I$16:$I$20))*$C$7 -> 0.013476495 | J28: =J10/SQRT(SUM($J$16:$J$20))*$C$8 -> 0.015944452 | K28: =K10/SQRT(SUM($K$16:$K$20))*$C$9 -> 0.084380278 | L28: =L10/SQRT(SUM($L$16:$L$20))*$C$10 -> 0.028531819 | M28: =M10/SQRT(SUM($M$16:$M$20))*$C$11 -> 0.08705891 | N28: =N10/SQRT(SUM($N$16:$N$20))*$C$12 -> 0.011355333 | O28: =O10/SQRT(SUM($O$16:$O$20))*$C$13 -> 0.038294417 | P28: =P10/SQRT(SUM($P$16:$P$20))*$C$14 -> 0.064424412 | Q28: =Q10/SQRT(SUM($Q$16:$Q$20))*$C$15 -> 0 | R28: =R10/SQRT(SUM($R$16:$R$20))*$C$16 -> 0.0082540199
E29: S5 | F29: =(F11/SQRT(SUM($F$16:$F$20)))*$C$4 -> 0.046894605 | G29: =(G11/SQRT(SUM($G$16:$G$20)))*$C$5 -> 0.032145508 | H29: =H11/SQRT(SUM($H$16:$H$20))*$C$6 -> 0.017330461 | I29: =I11/SQRT(SUM($I$16:$I$20))*$C$7 -> 0.011080673 | J29: =J11/SQRT(SUM($J$16:$J$20))*$C$8 -> 0.015944452 | K29: =K11/SQRT(SUM($K$16:$K$20))*$C$9 -> 0.084380278 | L29: =L11/SQRT(SUM($L$16:$L$20))*$C$10 -> 0.023776516 | M29: =M11/SQRT(SUM($M$16:$M$20))*$C$11 -> 0.043529455 | N29: =N11/SQRT(SUM($N$16:$N$20))*$C$12 -> 0.015897466 | O29: =O11/SQRT(SUM($O$16:$O$20))*$C$13 -> 0.032823786 | P29: =P11/SQRT(SUM($P$16:$P$20))*$C$14 -> 0.046017437 | Q29: =Q11/SQRT(SUM($Q$16:$Q$20))*$C$15 -> 0.021537098 | R29: =R11/SQRT(SUM($R$16:$R$20))*$C$16 -> 0.02476206
E30: A Max | F30: =MIN(F24:F28) -> 0.041684093 | G30: =MIN(G24:G28) -> 0.029350246 | H30: =MIN(H24:H28) -> 0.014179468 | I30: =MAX(I24:I28) -> 0.013476495 | J30: =MAX(J24:J28) -> 0.022322232 | K30: =MAX(K24:K28) -> 0.084380278 | L30: =MAX(L24:L28) -> 0.033287122 | M30: =MIN(M24:M28) -> 0.043529455 | N30: =MAX(N24:N28) -> 0.015897466 | O30: =MAX(O24:O28) -> 0.043765048 | P30: =MAX(P24:P28) -> 0.064424412 | Q30: =MIN(Q24:Q28) -> 0 | R30: =MAX(R24:R28) -> 0.0412701
E31: A Min | F31: =MAX(F25:F29) -> 0.06252614 | G31: =MAX(G25:G29) -> 0.033543139 | H31: =MAX(H25:H29) -> 0.017330461 | I31: =MIN(I25:I29) -> 0.010481718 | J31: =MIN(J25:J29) -> 0.009566671 | K31: =MIN(K25:K29) -> 0.036162976 | L31: =MIN(L25:L29) -> 0.023776516 | M31: =MAX(M25:M29) -> 0.08705891 | N31: =MIN(N25:N29) -> 0.0068131996 | O31: =MIN(O25:O29) -> 0.027353155 | P31: =MIN(P25:P29) -> 0.046017437 | Q31: =MAX(Q25:Q29) -> 0.053842745 | R31: =MIN(R25:R29) -> 0.0082540199
E33: A+ | F33: min | G33: min | H33: min | I33: max | J33: max | K33: max | L33: max | M33: min | N33: max | O33: max | P33: max | Q33: min | R33: max
E34: A- | F34: max | G34: max | H34: max | I34: min | J34: min | K34: min | L34: min | M34: max | N34: min | O34: min | P34: min | Q34: max | R34: min
E37: Tabel Rata-rata Nilai Kriteria Ternormalisasi Terbobot Kuadrat +
E38: Alternatives Supplier | F38: EKONOMI | J38: LINGKUNGAN | M38: SOSIAL | P38: ETIKA | S38: D+
F39: Kualitas | G39: Harga | H39: Delivery | I39: TKDN | J39: Eco-design | K39: Sistem Man. Lingkungan | L39: Green Image | M39: Sistem K3 | N39: CSR | O39: Education & Training | P39: CoC | Q39: CoI | R39: Transparansi Akuntansi Bisnis
E40: S1 | F40: =($F$30-F25)^2 -> 0.00010859773 | G40: =($G$30-G25)^2 -> 4.3950866e-06 | H40: =($H$30-H25)^2 -> 0 | I40: =($I$30-I25)^2 -> 8.9686866e-06 | J40: =($J$30-J25)^2 -> 0 | K40: =($K$30-K25)^2 -> 0.0023249082 | L40: =($L$30-L25)^2 -> 0 | M40: =($M$30-M25)^2 -> 0.0018948135 | N40: =($N$30-N25)^2 -> 2.0630973e-05 | O40: =($O$30-O25)^2 -> 0 | P40: =($P$30-P25)^2 -> 8.470418e-05 | Q40: =($Q$30-Q25)^2 -> 0.0004638466 | R40: =($R$30-R25)^2 -> 0.0010900615 | S40: =SQRT(SUM(F40:R40)) -> 0.077465647
E41: S2 | F41: =($F$30-F26)^2 -> 0.00043439091 | G41: =($G$30-G26)^2 -> 0 | H41: =($H$30-H26)^2 -> 2.4821891e-06 | I41: =($I$30-I26)^2 -> 2.2421717e-06 | J41: =($J$30-J26)^2 -> 0.00016270435 | K41: =($K$30-K26)^2 -> 0.00058122705 | L41: =($L$30-L26)^2 -> 9.0451632e-05 | M41: =($M$30-M26)^2 -> 0 | N41: =($N$30-N26)^2 -> 8.2523892e-05 | O41: =($O$30-O26)^2 -> 0.00026935023 | P41: =($P$30-P26)^2 -> 0.00033881672 | Q41: =($Q$30-Q26)^2 -> 0.0028990412 | R41: =($R$30-R26)^2 -> 0.00027251538 | S41: =SQRT(SUM(F41:R41)) -> 0.071664118
