Workbook

Sheet Kuesioner Expert 3
B6: Pemilihan Berdasarkan Kriteria
B7: Kriteria | C7: Kriteria Nilai | T7: Kriteria | V7: Kriteria | W7: Ekonomi | X7: Lingkungan | Y7: Etika | Z7: Sosial
C8: 9 | D8: 8 | E8: 7 | F8: 6 | G8: 5 | H8: 4 | I8: 3 | J8: 2 | K8: 1 | L8: 2 | M8: 3 | N8: 4 | O8: 5 | P8: 6 | Q8: 7 | R8: 8 | S8: 9 | V8: Ekonomi | W8: 1 | X8: =1/7 -> 0.14285714 | Y8: 3 | Z8: 3
B9: Faktor Ekonomi | Q9: x | T9: Faktor Lingkungan | V9: Lingkungan | W9: =1/X8 -> 7 | X9: 1 | Y9: 5 | Z9: 7
B10: Faktor Ekonomi | I10: x | T10: Faktor Sosial | V10: Etika | W10: =1/Y8 -> 0.33333333 | X10: =1/Y9 -> 0.2 | Y10: 1 | Z10: 7
B11: Faktor Ekonomi | I11: x | T11: Faktor Etika | V11: Sosial | W11: =1/Z8 -> 0.33333333 | X11: =1/Z9 -> 0.14285714 | Y11: =1/Z10 -> 0.14285714 | Z11: 1
B12: Faktor Lingkungan | E12: x | T12: Faktor Sosial
B13: Faktor Lingkungan | G13: x | T13: Faktor Etika
B14: Faktor Sosial | E14: x | T14: Faktor Etika
B16: Pemilihan Berdasarkan Sub-kriteria pada Faktor Ekonomi
B17: Sub-kriteria | C17: Kriteria Nilai | T17: Sub-kriteria | V17: Subkriteria | W17: Kualitas | X17: Harga | Y17: Pengiriman | Z17: TKDN
C18: 9 | D18: 8 | E18: 7 | F18: 6 | G18: 5 | H18: 4 | I18: 3 | J18: 2 | K18: 1 | L18: 2 | M18: 3 | N18: 4 | O18: 5 | P18: 6 | Q18: 7 | R18: 8 | S18: 9 | V18: Kualitas | W18: 1 | X18: 5 | Y18: 5 | Z18: 5
B19: Kualitas | G19: x | T19: Harga | V19: Harga | W19: =1/X18 -> 0.2 | X19: 1 | Y19: 3 | Z19: 3
B20: Kualitas | G20: x | T20: Pengiriman (Delivery) | V20: Pengiriman | W20: =1/Y18 -> 0.2 | X20: =1/Y19 -> 0.33333333 | Y20: 1 | Z20: =1/5 -> 0.2
B21: Kualitas | G21: x | T21: TKDN | V21: TKDN | W21: =1/Z18 -> 0.2 | X21: =1/Z19 -> 0.33333333 | Y21: =1/Z20 -> 5 | Z21: 1
B22: Harga | I22: x | T22: Pengiriman (Delivery)
B23: Harga | I23: x | T23: TKDN (Tingkat Komponen Dalam Negeri)
B24: Pengiriman (Delivery) | O24: x | T24: TKDN (Tingkat Komponen Dalam Negeri)
B26: Pemilihan Berdasarkan Sub-kriteria pada Faktor Lingkungan
B27: Sub-kriteria | C27: Kriteria Nilai | T27: Sub-kriteria | V27: Subkriteria | W27: Eco-Design | X27: SML | Y27: Green Image
C28: 9 | D28: 8 | E28: 7 | F28: 6 | G28: 5 | H28: 4 | I28: 3 | J28: 2 | K28: 1 | L28: 2 | M28: 3 | N28: 4 | O28: 5 | P28: 6 | Q28: 7 | R28: 8 | S28: 9 | V28: Eco-Design | W28: 1 | X28: =1/7 -> 0.14285714 | Y28: =1/3 -> 0.33333333
B29: Eco-Design | Q29: x | T29: Sistem Manajemen Lingkungan | V29: SML | W29: =1/X28 -> 7 | X29: 1 | Y29: 3
B30: Eco-Design | M30: x | T30: Green Image | V30: Green Image | W30: =1/Y28 -> 3 | X30: =1/Y29 -> 0.33333333 | Y30: 1
B31: Sistem Manajemen Lingkungan | I31: x | T31: Green Image
B33: Pemilihan Berdasarkan Sub-kriteria pada Faktor Sosial
B34: Sub-kriteria | C34: Kriteria Nilai | T34: Sub-kriteria | V34: Subkriteria | W34: SKK | X34: CSR | Y34: ET
C35: 9 | D35: 8 | E35: 7 | F35: 6 | G35: 5 | H35: 4 | I35: 3 | J35: 2 | K35: 1 | L35: 2 | M35: 3 | N35: 4 | O35: 5 | P35: 6 | Q35: 7 | R35: 8 | S35: 9 | V35: SKK | W35: 1 | X35: 7 | Y35: 5
B36: Sistem Kesehatan dan Keselamatan Kerja | E36: x | T36: Corporate Social Responsibility (CSR) | V36: CSR | W36: =1/X35 -> 0.14285714 | X36: 1 | Y36: 5
B37: Sistem Kesehatan dan Keselamatan Kerja | G37: x | T37: Education & Training | V37: ET | W37: =1/Y35 -> 0.2 | X37: =1/Y36 -> 0.2 | Y37: 1
B38: Corporate Social Responsibility (CSR) | G38: x | T38: Education & Training
B40: Pemilihan Berdasarkan Sub-kriteria pada Faktor Etika
B41: Sub-kriteria | C41: Kriteria Nilai | T41: Sub-kriteria | V41: Subkriteria | W41: CoC | X41: Col | Y41: TAB
C42: 9 | D42: 8 | E42: 7 | F42: 6 | G42: 5 | H42: 4 | I42: 3 | J42: 2 | K42: 1 | L42: 2 | M42: 3 | N42: 4 | O42: 5 | P42: 6 | Q42: 7 | R42: 8 | S42: 9 | V42: CoC | W42: 1 | X42: 5 | Y42: 5
B43: Code of Conduct (CoC) | G43: x | T43: Conflict of Interest (CoI) | V43: Col | W43: =1/X42 -> 0.2 | X43: 1 | Y43: 5
B44: Code of Conduct (CoC) | G44: x | T44: Transparasi dalam akuntansi dan bisnis | V44: TAB | W44: =1/Y42 -> 0.2 | X44: =1/Y43 -> 0.2 | Y44: 1
B45: Conflict of Interest (CoI) | G45: x | T45: Transparasi dalam akuntansi dan bisnis

Sheet Kuesioner Expert 2
B6: Pemilihan Berdasarkan Kriteria
B7: Kriteria | C7: Kriteria Nilai | T7: Kriteria | V7: Kriteria | W7: Ekonomi | X7: Lingkungan | Y7: Etika | Z7: Sosial
C8: 9 | D8: 8 | E8: 7 | F8: 6 | G8: 5 | H8: 4 | I8: 3 | J8: 2 | K8: 1 | L8: 2 | M8: 3 | N8: 4 | O8: 5 | P8: 6 | Q8: 7 | R8: 8 | S8: 9 | V8: Ekonomi | W8: 1 | X8: =1/7 -> 0.14285714 | Y8: 1 | Z8: 5
B9: Faktor Ekonomi | Q9: x | T9: Faktor Lingkungan | V9: Lingkungan | W9: =1/X8 -> 7 | X9: 1 | Y9: =1/3 -> 0.33333333 | Z9: 1
B10: Faktor Ekonomi | G10: x | T10: Faktor Sosial | V10: Etika | W10: =1/Y8 -> 1 | X10: =1/Y9 -> 3 | Y10: 1 | Z10: 5
B11: Faktor Ekonomi | K11: x | T11: Faktor Etika | V11: Sosial | W11: =1/Z8 -> 0.2 | X11: =1/Z9 -> 1 | Y11: =1/Z10 -> 0.2 | Z11: 1
B12: Faktor Lingkungan | K12: x | T12: Faktor Sosial
B13: Faktor Lingkungan | M13: x | T13: Faktor Etika
B14: Faktor Sosial | G14: x | T14: Faktor Etika
B16: Pemilihan Berdasarkan Sub-kriteria pada Faktor Ekonomi
B17: Sub-kriteria | C17: Kriteria Nilai | T17: Sub-kriteria | V17: Subkriteria | W17: Kualitas | X17: Harga | Y17: Pengiriman | Z17: TKDN
C18: 9 | D18: 8 | E18: 7 | F18: 6 | G18: 5 | H18: 4 | I18: 3 | J18: 2 | K18: 1 | L18: 2 | M18: 3 | N18: 4 | O18: 5 | P18: 6 | Q18: 7 | R18: 8 | S18: 9 | V18: Kualitas | W18: 1 | X18: 7 | Y18: 5 | Z18: 5
B19: Kualitas | E19: x | T19: Harga | V19: Harga | W19: =1/X18 -> 0.14285714 | X19: 1 | Y19: 1 | Z19: =1/3 -> 0.33333333
B20: Kualitas | G20: x | T20: Pengiriman (Delivery) | V20: Pengiriman | W20: =1/Y18 -> 0.2 | X20: =1/Y19 -> 1 | Y20: 1 | Z20: 3
B21: Kualitas | G21: x | T21: TKDN | V21: TKDN | W21: =1/Z18 -> 0.2 | X21: =1/Z19 -> 3 | Y21: =1/Z20 -> 0.33333333 | Z21: 1
B22: Harga | K22: x | T22: Pengiriman (Delivery)
B23: Harga | M23: x | T23: TKDN (Tingkat Komponen Dalam Negeri)
B24: Pengiriman (Delivery) | I24: x | T24: TKDN (Tingkat Komponen Dalam Negeri)
B26: Pemilihan Berdasarkan Sub-kriteria pada Faktor Lingkungan
B27: Sub-kriteria | C27: Kriteria Nilai | T27: Sub-kriteria | V27: Subkriteria | W27: Eco-Design | X27: SML | Y27: Green Image
C28: 9 | D28: 8 | E28: 7 | F28: 6 | G28: 5 | H28: 4 | I28: 3 | J28: 2 | K28: 1 | L28: 2 | M28: 3 | N28: 4 | O28: 5 | P28: 6 | Q28: 7 | R28: 8 | S28: 9 | V28: Eco-Design | W28: 1 | X28: 1 | Y28: 3
B29: Eco-Design | K29: x | T29: Sistem Manajemen Lingkungan | V29: SML | W29: =1/X28 -> 1 | X29: 1 | Y29: 1
B30: Eco-Design | I30: x | T30: Green Image | V30: Green Image | W30: =1/Y28 -> 0.33333333 | X30: =1/Y29 -> 1 | Y30: 1
B31: Sistem Manajemen Lingkungan | K31: x | T31: Green Image
B33: Pemilihan Berdasarkan Sub-kriteria pada Faktor Sosial
B34: Sub-kriteria | C34: Kriteria Nilai | T34: Sub-kriteria | V34: Subkriteria | W34: SKK | X34: CSR | Y34: ET
C35: 9 | D35: 8 | E35: 7 | F35: 6 | G35: 5 | H35: 4 | I35: 3 | J35: 2 | K35: 1 | L35: 2 | M35: 3 | N35: 4 | O35: 5 | P35: 6 | Q35: 7 | R35: 8 | S35: 9 | V35: SKK | W35: 1 | X35: 7 | Y35: 1
B36: Sistem Kesehatan dan Keselamatan Kerja | E36: x | T36: Corporate Social Responsibility (CSR) | V36: CSR | W36: =1/X35 -> 0.14285714 | X36: 1 | Y36: 5
B37: Sistem Kesehatan dan Keselamatan Kerja | K37: x | T37: Education & Training | V37: ET | W37: =1/Y35 -> 1 | X37: =1/Y36 -> 0.2 | Y37: 1
B38: Corporate Social Responsibility (CSR) | G38: x | T38: Education & Training
B40: Pemilihan Berdasarkan Sub-kriteria pada Faktor Etika
B41: Sub-kriteria | C41: Kriteria Nilai | T41: Sub-kriteria | V41: Subkriteria | W41: CoC | X41: Col | Y41: TAB
C42: 9 | D42: 8 | E42: 7 | F42: 6 | G42: 5 | H42: 4 | I42: 3 | J42: 2 | K42: 1 | L42: 2 | M42: 3 | N42: 4 | O42: 5 | P42: 6 | Q42: 7 | R42: 8 | S42: 9 | V42: CoC | W42: 1 | X42: 9 | Y42: 1
B43: Code of Conduct (CoC) | C43: x | T43: Conflict of Interest (CoI) | V43: Col | W43: =1/X42 -> 0.11111111 | X43: 1 | Y43: 1
B44: Code of Conduct (CoC) | K44: x | T44: Transparasi dalam akuntansi dan bisnis | V44: TAB | W44: =1/Y42 -> 1 | X44: =1/Y43 -> 1 | Y44: 1
B45: Conflict of Interest (CoI) | K45: x | T45: Transparasi dalam akuntansi dan bisnis

Sheet Kuesioner Expert 1
B6: Pemilihan Berdasarkan Kriteria
B7: Kriteria | C7: Kriteria Nilai | T7: Kriteria | V7: Kriteria | W7: Ekonomi | X7: Lingkungan | Y7: Etika | Z7: Sosial
C8: 9 | D8: 8 | E8: 7 | F8: 6 | G8: 5 | H8: 4 | I8: 3 | J8: 2 | K8: 1 | L8: 2 | M8: 3 | N8: 4 | O8: 5 | P8: 6 | Q8: 7 | R8: 8 | S8: 9 | V8: Ekonomi | W8: 1 | X8: 7 | Y8: 7 | Z8: 7
B9: Faktor Ekonomi | E9: x | T9: Faktor Lingkungan | V9: Lingkungan | W9: =1/X8 -> 0.14285714 | X9: 1 | Y9: 5 | Z9: 1
B10: Faktor Ekonomi | E10: x | T10: Faktor Sosial | V10: Etika | W10: =1/Y8 -> 0.14285714 | X10: =1/Y9 -> 0.2 | Y10: 1 | Z10: 5
B11: Faktor Ekonomi | E11: x | T11: Faktor Etika | V11: Sosial | W11: =1/Z8 -> 0.14285714 | X11: =1/Z9 -> 1 | Y11: =1/Z10 -> 0.2 | Z11: 1
B12: Faktor Lingkungan | K12: x | T12: Faktor Sosial
B13: Faktor Lingkungan | G13: x | T13: Faktor Etika
B14: Faktor Sosial | G14: x | T14: Faktor Etika
B16: Pemilihan Berdasarkan Sub-kriteria pada Faktor Ekonomi
B17: Sub-kriteria | C17: Kriteria Nilai | T17: Sub-kriteria | V17: Subkriteria | W17: Kualitas | X17: Harga | Y17: Pengiriman | Z17: TKDN
C18: 9 | D18: 8 | E18: 7 | F18: 6 | G18: 5 | H18: 4 | I18: 3 | J18: 2 | K18: 1 | L18: 2 | M18: 3 | N18: 4 | O18: 5 | P18: 6 | Q18: 7 | R18: 8 | S18: 9 | V18: Kualitas | W18: 1 | X18: =1/9 -> 0.11111111 | Y18: 1 | Z18: 7
B19: Kualitas | S19: x | T19: Harga | V19: Harga | W19: =1/X18 -> 9 | X19: 1 | Y19: 5 | Z19: 7
B20: Kualitas | K20: x | T20: Pengiriman (Delivery) | V20: Pengiriman | W20: =1/Y18 -> 1 | X20: =1/Y19 -> 0.2 | Y20: 1 | Z20: 7
B21: Kualitas | E21: x | T21: TKDN | V21: TKDN | W21: =1/Z18 -> 0.14285714 | X21: =1/Z19 -> 0.14285714 | Y21: =1/Z20 -> 0.14285714 | Z21: 1
B22: Harga | G22: x | T22: Pengiriman (Delivery)
B23: Harga | E23: x | T23: TKDN (Tingkat Komponen Dalam Negeri)
B24: Pengiriman (Delivery) | E24: x | T24: TKDN (Tingkat Komponen Dalam Negeri)
B26: Pemilihan Berdasarkan Sub-kriteria pada Faktor Lingkungan
B27: Sub-kriteria | C27: Kriteria Nilai | T27: Sub-kriteria | V27: Subkriteria | W27: Eco-Design | X27: SML | Y27: Green Image
C28: 9 | D28: 8 | E28: 7 | F28: 6 | G28: 5 | H28: 4 | I28: 3 | J28: 2 | K28: 1 | L28: 2 | M28: 3 | N28: 4 | O28: 5 | P28: 6 | Q28: 7 | R28: 8 | S28: 9 | V28: Eco-Design | W28: 1 | X28: =1/7 -> 0.14285714 | Y28: =1/7 -> 0.14285714
B29: Eco-Design | Q29: x | T29: Sistem Manajemen Lingkungan | V29: SML | W29: =1/X28 -> 7 | X29: 1 | Y29: 7
B30: Eco-Design | Q30: x | T30: Green Image | V30: Green Image | W30: =1/Y28 -> 7 | X30: =1/Y29 -> 0.14285714 | Y30: 1
B31: Sistem Manajemen Lingkungan | E31: x | T31: Green Image
B33: Pemilihan Berdasarkan Sub-kriteria pada Faktor Sosial
B34: Sub-kriteria | C34: Kriteria Nilai | T34: Sub-kriteria | V34: Subkriteria | W34: SKK | X34: CSR | Y34: ET
C35: 9 | D35: 8 | E35: 7 | F35: 6 | G35: 5 | H35: 4 | I35: 3 | J35: 2 | K35: 1 | L35: 2 | M35: 3 | N35: 4 | O35: 5 | P35: 6 | Q35: 7 | R35: 8 | S35: 9 | V35: SKK | W35: 1 | X35: 7 | Y35: 7
B36: Sistem Kesehatan dan Keselamatan Kerja | E36: x | T36: Corporate Social Responsibility (CSR) | V36: CSR | W36: =1/X35 -> 0.14285714 | X36: 1 | Y36: 1
B37: Sistem Kesehatan dan Keselamatan Kerja | E37: x | T37: Education & Training | V37: ET | W37: =1/Y35 -> 0.14285714 | X37: =1/Y36 -> 1 | Y37: 1
B38: Corporate Social Responsibility (CSR) | K38: x | T38: Education & Training
B40: Pemilihan Berdasarkan Sub-kriteria pada Faktor Etika
B41: Sub-kriteria | C41: Kriteria Nilai | T41: Sub-kriteria | V41: Subkriteria | W41: CoC | X41: Col | Y41: TAB
C42: 9 | D42: 8 | E42: 7 | F42: 6 | G42: 5 | H42: 4 | I42: 3 | J42: 2 | K42: 1 | L42: 2 | M42: 3 | N42: 4 | O42: 5 | P42: 6 | Q42: 7 | R42: 8 | S42: 9 | V42: CoC | W42: 1 | X42: 1 | Y42: 1
B43: Code of Conduct (CoC) | K43: x | T43: Conflict of Interest (CoI) | V43: Col | W43: =1/X42 -> 1 | X43: 1 | Y43: 1
B44: Code of Conduct (CoC) | K44: x | T44: Transparasi dalam akuntansi dan bisnis | V44: TAB | W44: =1/Y42 -> 1 | X44: =1/Y43 -> 1 | Y44: 1
B45: Conflict of Interest (CoI) | K45: x | T45: Transparasi dalam akuntansi dan bisnis

Sheet Supplier Info
B2: Alternatives Supplier | C2: EKONOMI | G2: LINGKUNGAN | J2: SOSIAL | M2: ETIKA
C3: Kualitas | D3: Harga | E3: Delivery | F3: TKDN | G3: Eco-design | H3: Sistem Man. Lingkungan | I3: Green Image | J3: Sistem K3 | K3: CSR | L3: Education & Training | M3: CoC | N3: CoI | O3: Transparansi Akuntansi Bisnis
C4: DPMO | D4: USD | E4: Days | F4: % | G4: High-Low (Rating 0-7) | H4: High-Low (Rating 0-7) | I4: High-Low (Rating 0-7) | J4: Lost Time Injury Freq. Rate | K4: High-Low (Rating 0-7) | L4: No. of Training Sessions | M4: High-Low (Rating 0-7) | N4: No. of Cases | O4: Disclosure level
B5: S1 | C5: 200 | D5: 4500000 | E5: 180 | F5: 35 | G5: 7 | H5: 3 | I5: 7 | J5: 2 | K5: 5 | L5: 8 | M5: 6 | N5: 2 | O5: 1
B6: S2 | C6: 240 | D6: 4200000 | E6: 200 | F6: 40 | G6: 3 | H6: 5 | I6: 5 | J6: 1 | K6: 3 | L6: 5 | M6: 5 | N6: 5 | O6: 3
B7: S3 | C7: 160 | D7: 4800000 | E7: 200 | F7: 38 | G7: 5 | H7: 5 | I7: 6 | J7: 1 | K7: 7 | L7: 5 | M7: 7 | N7: 3 | O7: 5
B8: S4 | C8: 220 | D8: 4300000 | E8: 220 | F8: 45 | G8: 5 | H8: 7 | I8: 6 | J8: 2 | K8: 5 | L8: 7 | M8: 7 | N8: 0 | O8: 1
B9: S5 | C9: 180 | D9: 4600000 | E9: 220 | F9: 37 | G9: 5 | H9: 7 | I9: 5 | J9: 1 | K9: 7 | L9: 6 | M9: 5 | N9: 2 | O9: 3
C10: min | D10: min | E10: min | F10: max | G10: max | H10: max | I10: max | J10: min | K10: max | L10: max | M10: max | N10: min | O10: max
B12: Saran perbaikan:
B13: tambahkan expert di bagian HSE
B14: tambahkan subkriteria Polution Control, MCU procedure and records, and Human Rights
B15: tambahkan kriteria flexibility
B16: hubungan antara kriteria dan bobot kriteria
E40: 0.48
E41: 0.24
E42: 0.16
E43: 0.12
E44: =SUM(E40:E43) -> 1
M61: 0.1941
M62: 0.1567
M63: 0.0655
M64: 0.0331
M65: 0.0091
M66: 0.0528
M67: 0.0583
M68: 0.0171
M69: 0.0334
M70: 0.113
M71: 0.0803
M72: 0.039
... M76: 0.0401
M78: =SUM(M61:M77) -> 1

Sheet AHP
A1: Jumlah Elemen | B1: 1 | C1: 2 | D1: 3 | E1: 4 | F1: 5 | G1: 6 | H1: 7 | I1: 8 | J1: 9 | K1: 10 | L1: 11 | M1: 12
A2: Rasio Indeks | B2: 0 | C2: 0 | D2: 0.58 | E2: 0.9 | F2: 1.12 | G2: 1.24 | H2: 1.32 | I2: 1.41 | J2: 1.45 | K2: 1.49 | L2: 1.52 | M2: 1.54
A4: Perhitungan AHP Pada Kriteria
B5: Expert 1 Kuesioner
B6: Kriteria | C6: Ekonomi | D6: Lingkungan | E6: Etika | F6: Sosial
B7: Ekonomi | C7: 1 | D7: 7 | E7: 7 | F7: 7
B8: Lingkungan | C8: =1/D7 -> 0.14285714 | D8: 1 | E8: 5 | F8: 4
B9: Etika | C9: =1/E7 -> 0.14285714 | D9: =1/E8 -> 0.2 | E9: 1 | F9: 5
B10: Sosial | C10: =1/F7 -> 0.14285714 | D10: =1/F8 -> 0.25 | E10: =1/F9 -> 0.2 | F10: 1
B11: Expert 2 Kuesioner
B12: Kriteria | C12: Ekonomi | D12: Lingkungan | E12: Etika | F12: Sosial
B13: Ekonomi | C13: 1 | D13: =1/7 -> 0.14285714 | E13: 1 | F13: 5 | H13: Kriteria | I13: Ekonomi | J13: Lingkungan | K13: Etika | L13: Sosial
B14: Lingkungan | C14: =1/D13 -> 7 | D14: 1 | E14: =1/3 -> 0.33333333 | F14: 3 | H14: Ekonomi | I14: 1 | J14: =GEOMEAN(D7,D19,D13) -> 0.52275796 | K14: =GEOMEAN(E7,E19,E13) -> 2.7589242 | L14: =GEOMEAN(F7,F19,F13) -> 4.717694
B15: Etika | C15: =1/E13 -> 1 | D15: =1/E14 -> 3 | E15: 1 | F15: 5 | H15: Lingkungan | I15: =1/J14 -> 1.9129312 | J15: 1 | K15: =GEOMEAN(E8,E20,E14) -> 2.0274007 | L15: =GEOMEAN(F8,F20,F14) -> 4.3795191
B16: Sosial | C16: =1/F13 -> 0.2 | D16: =1/F14 -> 0.33333333 | E16: =1/F15 -> 0.2 | F16: 1 | H16: Etika | I16: =1/K14 -> 0.36246012 | J16: =1/K15 -> 0.49324241 | K16: 1 | L16: =GEOMEAN(F9,F21,F15) -> 5.5934447
B17: Expert 3 Kuesioner | H17: Sosial | I17: =1/L14 -> 0.21196797 | J17: =1/L15 -> 0.22833557 | K17: =1/L16 -> 0.17878071 | L17: 1
B18: Kriteria | C18: Ekonomi | D18: Lingkungan | E18: Etika | F18: Sosial | H18: Total | I18: =SUM(I14:I17) -> 3.4873593 | J18: =SUM(J14:J17) -> 2.2443359 | K18: =SUM(K14:K17) -> 5.9651055 | L18: =SUM(L14:L17) -> 15.690658
B19: Ekonomi | C19: 1 | D19: =1/7 -> 0.14285714 | E19: 3 | F19: 3
B20: Lingkungan | C20: =1/D19 -> 7 | D20: 1 | E20: 5 | F20: 7 | H20: Tabel Normalisasi
B21: Etika | C21: =1/E19 -> 0.33333333 | D21: =1/E20 -> 0.2 | E21: 1 | F21: 7 | H21: Kriteria | I21: Ekonomi | J21: Lingkungan | K21: Etika | L21: Sosial | M21: Priority Vector | N21: Hasil Kali | O21: HK/PV
B22: Sosial | C22: =1/F19 -> 0.33333333 | D22: =1/F20 -> 0.14285714 | E22: =1/F21 -> 0.14285714 | F22: 1 | H22: Ekonomi | I22: =I14/$I$18 -> 0.28674992 | J22: =J14/$J$18 -> 0.23292322 | K22: =K14/$K$18 -> 0.46251054 | L22: =L14/$L$18 -> 0.30066897 | M22: =SUM(I22:L22)/4 -> 0.32071316 | N22: =MMULT(I14:L14,$M$22:$M$25) -> 1.4184993 | O22: =N22/M22 -> 4.4229533
H23: Lingkungan | I23: =I15/$I$18 -> 0.54853287 | J23: =J15/$J$18 -> 0.44556609 | K23: =K15/$K$18 -> 0.33987675 | L23: =L15/$L$18 -> 0.27911635 | M23: =SUM(I23:L23)/4 -> 0.40327301 | N23: =MMULT(I15:L15,$M$22:$M$25) -> 1.7270329 | O23: =N23/M23 -> 4.2825403
H24: Etika | I24: =I16/$I$18 -> 0.10393541 | J24: =J16/$J$18 -> 0.2197721 | K24: =K16/$K$18 -> 0.16764163 | L24: =L16/$L$18 -> 0.35648249 | M24: =SUM(I24:L24)/4 -> 0.21195791 | N24: =MMULT(I16:L16,$M$22:$M$25) -> 0.88540822 | O24: =N24/M24 -> 4.1772833
H25: Sosial | I25: =I17/$I$18 -> 0.060781798 | J25: =J17/$J$18 -> 0.10173859 | K25: =K17/$K$18 -> 0.029971089 | L25: =L17/$L$18 -> 0.063732191 | M25: =SUM(I25:L25)/4 -> 0.064055916 | N25: =MMULT(I17:L17,$M$22:$M$25) -> 0.26201239 | O25: =N25/M25 -> 4.0903699
H26: Total | I26: =SUM(I22:I25) -> 1 | J26: =SUM(J22:J25) -> 1 | K26: =SUM(K22:K25) -> 1 | L26: =SUM(L22:L25) -> 1
O27: Lambda | P27: =AVERAGE(O22:O25) -> 4.2432867 | Q27: Kesimpulan
O28: Elemen | P28: 4 | Q28: =IF(P31<=0.1,"Konsisten","Tidak Konsisten") -> Konsisten
O29: CI | P29: =(P27-P28)/(P28-1) -> 0.081095565 | Q29: Note: Konsisten jika bernilai <= 0,1
O30: RI | P30: =$E$2 -> 0.9
O31: CR | P31: =P29/P30 -> 0.090106184
A34: Perhitungan AHP Pada Tiap-tiap Subkriteria
A35: Ekonomi
B36: Expert 1 Kuesioner
B37: Subkriteria | C37: Kualitas | D37: Harga | E37: Pengiriman | F37: TKDN
B38: Kualitas | C38: 1 | D38: =1/9 -> 0.11111111 | E38: 1 | F38: 7
B39: Harga | C39: =1/D38 -> 9 | D39: 1 | E39: 5 | F39: 7
B40: Pengiriman | C40: =1/E38 -> 1 | D40: =1/E39 -> 0.2 | E40: 1 | F40: 7
B41: TKDN | C41: =1/F38 -> 0.14285714 | D41: =1/F39 -> 0.14285714 | E41: =1/F40 -> 0.14285714 | F41: 1
B42: Expert 2 Kuesioner
B43: Subkriteria | C43: Kualitas | D43: Harga | E43: Pengiriman | F43: TKDN
...

Sheet AHP edit
A1: Jumlah Elemen | B1: 1 | C1: 2 | D1: 3 | E1: 4 | F1: 5 | G1: 6 | H1: 7 | I1: 8 | J1: 9 | K1: 10 | L1: 11 | M1: 12
A2: Rasio Indeks | B2: 0 | C2: 0 | D2: 0.58 | E2: 0.9 | F2: 1.12 | G2: 1.24 | H2: 1.32 | I2: 1.41 | J2: 1.45 | K2: 1.49 | L2: 1.52 | M2: 1.54
A4: Perhitungan AHP Pada Kriteria
B5: Expert 1 Kuesioner
B6: Kriteria | C6: Ekonomi | D6: Lingkungan | E6: Sosial | F6: Etika
B7: Ekonomi | C7: 1 | D7: 5 | E7: 3 | F7: 7
B8: Lingkungan | C8: =1/D7 -> 0.2 | D8: 1 | E8: 3 | F8: 5
B9: Sosial | C9: =1/E7 -> 0.33333333 | D9: =1/E8 -> 0.33333333 | E9: 1 | F9: 5
B10: Etika | C10: =1/F7 -> 0.14285714 | D10: =1/F8 -> 0.2 | E10: =1/F9 -> 0.2 | F10: 1
B11: Expert 2 Kuesioner
B12: Kriteria | C12: Ekonomi | D12: Lingkungan | E12: Sosial | F12: Etika
B13: Ekonomi | C13: 1 | D13: =1/3 -> 0.33333333 | E13: 3 | F13: 5 | H13: Kriteria | I13: Ekonomi | J13: Lingkungan | K13: Sosial | L13: Etika
B14: Lingkungan | C14: =1/D13 -> 3 | D14: 1 | E14: 3 | F14: 5 | H14: Ekonomi | I14: 1 | J14: =GEOMEAN(D7,D19,D13) -> 0.61979809 | K14: =GEOMEAN(E7,E19,E13) -> 3.9790572 | L14: =GEOMEAN(F7,F19,F13) -> 4.717694
B15: Sosial | C15: =1/E13 -> 0.33333333 | D15: =1/E14 -> 0.33333333 | E15: 1 | F15: 3 | H15: Lingkungan | I15: =1/J14 -> 1.6134286 | J15: 1 | K15: =GEOMEAN(E8,E20,E14) -> 3.5568933 | L15: =GEOMEAN(F8,F20,F14) -> 5.5934447
B16: Etika | C16: =1/F13 -> 0.2 | D16: =1/F14 -> 0.2 | E16: =1/F15 -> 0.33333333 | F16: 1 | H16: Etika | I16: =1/K14 -> 0.25131581 | J16: =1/K15 -> 0.28114422 | K16: 1 | L16: =GEOMEAN(F9,F21,F15) -> 4.717694
B17: Expert 3 Kuesioner | H17: Sosial | I17: =1/L14 -> 0.21196797 | J17: =1/L15 -> 0.17878071 | K17: =1/L16 -> 0.21196797 | L17: 1
B18: Kriteria | C18: Ekonomi | D18: Lingkungan | E18: Sosial | F18: Etika | H18: Total | I18: =SUM(I14:I17) -> 3.0767124 | J18: =SUM(J14:J17) -> 2.079723 | K18: =SUM(K14:K17) -> 8.7479185 | L18: =SUM(L14:L17) -> 16.028833
B19: Ekonomi | C19: 1 | D19: =1/7 -> 0.14285714 | E19: 7 | F19: 3
B20: Lingkungan | C20: =1/D19 -> 7 | D20: 1 | E20: 5 | F20: 7 | H20: Tabel Normalisasi
B21: Sosial | C21: =1/E19 -> 0.14285714 | D21: =1/E20 -> 0.2 | E21: 1 | F21: 7 | H21: Kriteria | I21: Ekonomi | J21: Lingkungan | K21: Sosial | L21: Etika | M21: Priority Vector | N21: Hasil Kali | O21: HK/PV
B22: Etika | C22: =1/F19 -> 0.33333333 | D22: =1/F20 -> 0.14285714 | E22: =1/F21 -> 0.14285714 | F22: 1 | H22: Ekonomi | I22: =I14/$I$18 -> 0.32502225 | J22: =J14/$J$18 -> 0.29801954 | K22: =K14/$K$18 -> 0.4548576 | L22: =L14/$L$18 -> 0.29432549 | M22: =SUM(I22:L22)/4 -> 0.34305622 | N22: =MMULT(I14:L14,$M$22:$M$25) -> 1.5229233 | O22: =N22/M22 -> 4.439282
H23: Lingkungan | I23: =I15/$I$18 -> 0.52440021 | J23: =J15/$J$18 -> 0.48083326 | K23: =K15/$K$18 -> 0.40659882 | L23: =L15/$L$18 -> 0.34896145 | M23: =SUM(I23:L23)/4 -> 0.44019843 | N23: =MMULT(I15:L15,$M$22:$M$25) -> 1.8875799 | O23: =N23/M23 -> 4.2880206
H24: Etika | I24: =I16/$I$18 -> 0.081683232 | J24: =J16/$J$18 -> 0.13518349 | K24: =K16/$K$18 -> 0.11431291 | L24: =L16/$L$18 -> 0.29432549 | M24: =SUM(I24:L24)/4 -> 0.15637628 | N24: =MMULT(I16:L16,$M$22:$M$25) -> 0.65115376 | O24: =N24/M24 -> 4.1640187
H25: Sosial | I25: =I17/$I$18 -> 0.068894306 | J25: =J17/$J$18 -> 0.08596371 | K25: =K17/$K$18 -> 0.024230675 | L25: =L17/$L$18 -> 0.062387575 | M25: =SUM(I25:L25)/4 -> 0.060369066 | N25: =MMULT(I17:L17,$M$22:$M$25) -> 0.24493174 | O25: =N25/M25 -> 4.0572392
H26: Total | I26: =SUM(I22:I25) -> 1 | J26: =SUM(J22:J25) -> 1 | K26: =SUM(K22:K25) -> 1 | L26: =SUM(L22:L25) -> 1
O27: Lambda | P27: =AVERAGE(O22:O25) -> 4.2371402 | Q27: Kesimpulan
O28: Elemen | P28: 4 | Q28: =IF(P31<=0.1,"Konsisten","Tidak Konsisten") -> Konsisten
O29: CI | P29: =(P27-P28)/(P28-1) -> 0.079046717 | Q29: Note: Konsisten jika bernilai <= 0,1
O30: RI | P30: =$E$2 -> 0.9
O31: CR | P31: =P29/P30 -> 0.087829685
A34: Perhitungan AHP Pada Tiap-tiap Subkriteria
A35: Ekonomi
B36: Expert 1 Kuesioner
B37: Subkriteria | C37: Kualitas | D37: Harga | E37: Pengiriman | F37: TKDN
B38: Kualitas | C38: 1 | D38: =1/9 -> 0.11111111 | E38: 1 | F38: 7
B39: Harga | C39: =1/D38 -> 9 | D39: 1 | E39: 5 | F39: 7
B40: Pengiriman | C40: =1/E38 -> 1 | D40: =1/E39 -> 0.2 | E40: 1 | F40: 7
B41: TKDN | C41: =1/F38 -> 0.14285714 | D41: =1/F39 -> 0.14285714 | E41: =1/F40 -> 0.14285714 | F41: 1
B42: Expert 2 Kuesioner
B43: Subkriteria | C43: Kualitas | D43: Harga | E43: Pengiriman | F43: TKDN
...

Sheet AHP-Topsis
A1: Tabel Nilai Sub Kriteria
A3: Kriteria | B3: Sub Kriteria | E3: Tabel Alternatif dan Sub Kriteria
A4: Ekonomi C01 | B4: Kualitas | C4: ='AHP edit'!M53/4 -> 0.11766992 | E4: Alternatives Supplier | F4: EKONOMI | J4: LINGKUNGAN | M4: SOSIAL | P4: ETIKA
B5: Harga | C5: ='AHP edit'!M54/4 -> 0.070083903 | F5: Kualitas | G5: Harga | H5: Delivery | I5: TKDN | J5: Eco-design | K5: Sistem Man. Lingkungan | L5: Green Image | M5: Sistem K3 | N5: CSR | O5: Education & Training | P5: CoC | Q5: CoI | R5: Transparansi Akuntansi Bisnis
B6: Pengiriman | C6: ='AHP edit'!M55/4 -> 0.036030333 | F6: DPMO | G6: USD | H6: Days | I6: % | J6: High-Low (Rating 0-7) | K6: High-Low (Rating 0-7) | L6: High-Low (Rating 0-7) | M6: Lost Time Injury Freq. Rate | N6: High-Low (Rating 0-7) | O6: No. of Training Sessions | P6: High-Low (Rating 0-7) | Q6: No. of Cases | R6: Disclosure level
B7: TKDN | C7: ='AHP edit'!M56/4 -> 0.026215844 | E7: S1 | F7: 200 | G7: 4500000 | H7: 180 | I7: 35 | J7: 7 | K7: 3 | L7: 7 | M7: 2 | N7: 5 | O7: 8 | P7: 6 | Q7: 2 | R7: 1
A8: Lingkungan C02 | B8: Eco-Design | C8: ='AHP edit'!K80/4 -> 0.036776077 | E8: S2 | F8: 240 | G8: 4200000 | H8: 200 | I8: 40 | J8: 3 | K8: 5 | L8: 5 | M8: 1 | N8: 3 | O8: 5 | P8: 5 | Q8: 5 | R8: 3
B9: SML | C9: ='AHP edit'!K81/4 -> 0.15104027 | E9: S3 | F9: 160 | G9: 4800000 | H9: 200 | I9: 38 | J9: 5 | K9: 5 | L9: 6 | M9: 1 | N9: 7 | O9: 5 | P9: 7 | Q9: 3 | R9: 5
B10: Green Image | C10: ='AHP edit'!K82/4 -> 0.062183657 | E10: S4 | F10: 220 | G10: 4300000 | H10: 220 | I10: 45 | J10: 5 | K10: 7 | L10: 6 | M10: 2 | N10: 5 | O10: 7 | P10: 7 | Q10: 0 | R10: 1
A11: Sosial C03 | B11: SKK | C11: ='AHP edit'!K105/4 -> 0.14437087 | E11: S5 | F11: 180 | G11: 4600000 | H11: 220 | I11: 37 | J11: 5 | K11: 7 | L11: 5 | M11: 1 | N11: 7 | O11: 6 | P11: 5 | Q11: 2 | R11: 3
B12: CSR | C12: ='AHP edit'!K106/4 -> 0.028456382
B13: ET | C13: ='AHP edit'!K107/4 -> 0.077172748 | E13: Tabel Alternatif dan Sub Kriteria Kuadrat
A14: Etika C04 | B14: CoC | C14: ='AHP edit'!K130/4 -> 0.12484218 | E14: Alternatives Supplier | F14: EKONOMI | J14: LINGKUNGAN | M14: SOSIAL | P14: ETIKA
B15: Col | C15: ='AHP edit'!K131/4 -> 0.069788174 | F15: Kualitas | G15: Harga | H15: Delivery | I15: TKDN | J15: Eco-design | K15: Sistem Man. Lingkungan | L15: Green Image | M15: Sistem K3 | N15: CSR | O15: Education & Training | P15: CoC | Q15: CoI | R15: Transparansi Akuntansi Bisnis
B16: TAB | C16: ='AHP edit'!K132/4 -> 0.055369649 | E16: S1 | F16: =F7^2 -> 40000 | G16: =G7^2 -> 20250000000000 | H16: =H7^2 -> 32400 | I16: =I7^2 -> 1225 | J16: =J7^2 -> 49 | K16: =K7^2 -> 9 | L16: =L7^2 -> 49 | M16: =M7^2 -> 4 | ... R16: =R7^2 -> 1
E17: S2 | F17: =F8^2 -> 57600 | G17: =G8^2 -> 17640000000000 | H17: =H8^2 -> 40000 | I17: =I8^2 -> 1600 | J17: =J8^2 -> 9 | K17: =K8^2 -> 25 | L17: =L8^2 -> 25 | M17: =M8^2 -> 1 | ... R17: =R8^2 -> 9
E18: S3 | F18: =F9^2 -> 25600 | G18: =G9^2 -> 23040000000000 | H18: =H9^2 -> 40000 | I18: =I9^2 -> 1444 | J18: =J9^2 -> 25 | K18: =K9^2 -> 25 | L18: =L9^2 -> 36 | M18: =M9^2 -> 1 | ... R18: =R9^2 -> 25
E19: S4 | F19: =F10^2 -> 48400 | G19: =G10^2 -> 18490000000000 | H19: =H10^2 -> 48400 | I19: =I10^2 -> 2025 | J19: =J10^2 -> 25 | K19: =K10^2 -> 49 | L19: =L10^2 -> 36 | M19: =M10^2 -> 4 | ... R19: =R10^2 -> 1
E20: S5 | F20: =F11^2 -> 32400 | G20: =G11^2 -> 21160000000000 | H20: =H11^2 -> 48400 | I20: =I11^2 -> 1369 | J20: =J11^2 -> 25 | K20: =K11^2 -> 49 | L20: =L11^2 -> 25 | M20: =M11^2 -> 1 | ... R20: =R11^2 -> 9
E22: Tabel Rata-rata Nilai Kriteria
E23: Alternatives Supplier | F23: EKONOMI | J23: LINGKUNGAN | M23: SOSIAL | P23: ETIKA
F24: Kualitas | G24: Harga | H24: Delivery | I24: TKDN | J24: Eco-design | K24: Sistem Man. Lingkungan | L24: Green Image | M24: Sistem K3 | N24: CSR | O24: Education & Training | P24: CoC | Q24: CoI | R24: Transparansi Akuntansi Bisnis
E25: S1 | F25: =F7/SQRT(SUM($F$16:$F$20)) -> 0.44280744 | G25: =G7/SQRT(SUM($G$16:$G$20)) -> 0.44870065 | H25: =H7/SQRT(SUM($H$16:$H$20)) -> 0.39354252 | I25: =I7/SQRT(SUM($I$16:$I$20)) -> 0.39982379 | J25: =J7/SQRT(SUM($J$16:$J$20)) -> 0.60697698 | K25: =K7/SQRT(SUM($K$16:$K$20)) -> 0.23942607 | L25: =L7/SQRT(SUM($L$16:$L$20)) -> 0.53530338 | M25: =M7/SQRT(SUM($M$16:$M$20)) -> 0.60302269 | N25: =N7/SQRT(SUM($N$16:$N$20)) -> 0.39904344 | O25: =O7/SQRT(SUM($O$16:$O$20)) -> 0.56710496 | P25: =P7/SQRT(SUM($P$16:$P$20)) -> 0.44232587 | Q25: =Q7/SQRT(SUM($Q$16:$Q$20)) -> 0.3086067 | R25: =R7/SQRT(SUM($R$16:$R$20)) -> 0.1490712
E26: S2 | F26: =F8/SQRT(SUM($F$16:$F$20)) -> 0.53136893 | G26: =G8/SQRT(SUM($G$16:$G$20)) -> 0.41878727 | H26: =H8/SQRT(SUM($H$16:$H$20)) -> 0.43726947 | I26: =I8/SQRT(SUM($I$16:$I$20)) -> 0.45694147 | J26: =J8/SQRT(SUM($J$16:$J$20)) -> 0.26013299 | K26: =K8/SQRT(SUM($K$16:$K$20)) -> 0.39904344 | L26: =L8/SQRT(SUM($L$16:$L$20)) -> 0.38235956 | M26: =M8/SQRT(SUM($M$16:$M$20)) -> 0.30151134 | N26: =N8/SQRT(SUM($N$16:$N$20)) -> 0.23942607 | O26: =O8/SQRT(SUM($O$16:$O$20)) -> 0.3544406 | P26: =P8/SQRT(SUM($P$16:$P$20)) -> 0.36860489 | Q26: =Q8/SQRT(SUM($Q$16:$Q$20)) -> 0.77151675 | R26: =R8/SQRT(SUM($R$16:$R$20)) -> 0.4472136
E27: S3 | F27: =F9/SQRT(SUM($F$16:$F$20)) -> 0.35424595 | G27: =G9/SQRT(SUM($G$16:$G$20)) -> 0.47861403 | H27: =H9/SQRT(SUM($H$16:$H$20)) -> 0.43726947 | I27: =I9/SQRT(SUM($I$16:$I$20)) -> 0.4340944 | J27: =J9/SQRT(SUM($J$16:$J$20)) -> 0.43355498 | K27: =K9/SQRT(SUM($K$16:$K$20)) -> 0.39904344 | L27: =L9/SQRT(SUM($L$16:$L$20)) -> 0.45883147 | M27: =M9/SQRT(SUM($M$16:$M$20)) -> 0.30151134 | N27: =N9/SQRT(SUM($N$16:$N$20)) -> 0.55866082 | O27: =O9/SQRT(SUM($O$16:$O$20)) -> 0.3544406 | P27: =P9/SQRT(SUM($P$16:$P$20)) -> 0.51604685 | Q27: =Q9/SQRT(SUM($Q$16:$Q$20)) -> 0.46291005 | R27: =R9/SQRT(SUM($R$16:$R$20)) -> 0.74535599
E28: S4 | F28: =F10/SQRT(SUM($F$16:$F$20)) -> 0.48708819 | G28: =G10/SQRT(SUM($G$16:$G$20)) -> 0.4287584 | H28: =H10/SQRT(SUM($H$16:$H$20)) -> 0.48099642 | I28: =I10/SQRT(SUM($I$16:$I$20)) -> 0.51405916 | J28: =J10/SQRT(SUM($J$16:$J$20)) -> 0.43355498 | K28: =K10/SQRT(SUM($K$16:$K$20)) -> 0.55866082 | L28: =L10/SQRT(SUM($L$16:$L$20)) -> 0.45883147 | M28: =M10/SQRT(SUM($M$16:$M$20)) -> 0.60302269 | N28: =N10/SQRT(SUM($N$16:$N$20)) -> 0.39904344 | O28: =O10/SQRT(SUM($O$16:$O$20)) -> 0.49621684 | P28: =P10/SQRT(SUM($P$16:$P$20)) -> 0.51604685 | Q28: =Q10/SQRT(SUM($Q$16:$Q$20)) -> 0 | R28: =R10/SQRT(SUM($R$16:$R$20)) -> 0.1490712
E29: S5 | F29: =F11/SQRT(SUM($F$16:$F$20)) -> 0.3985267 | G29: =G11/SQRT(SUM($G$16:$G$20)) -> 0.45867177 | H29: =H11/SQRT(SUM($H$16:$H$20)) -> 0.48099642 | I29: =I11/SQRT(SUM($I$16:$I$20)) -> 0.42267086 | J29: =J11/SQRT(SUM($J$16:$J$20)) -> 0.43355498 | K29: =K11/SQRT(SUM($K$16:$K$20)) -> 0.55866082 | L29: =L11/SQRT(SUM($L$16:$L$20)) -> 0.38235956 | M29: =M11/SQRT(SUM($M$16:$M$20)) -> 0.30151134 | N29: =N11/SQRT(SUM($N$16:$N$20)) -> 0.55866082 | O29: =O11/SQRT(SUM($O$16:$O$20)) -> 0.42532872 | P29: =P11/SQRT(SUM($P$16:$P$20)) -> 0.36860489 | Q29: =Q11/SQRT(SUM($Q$16:$Q$20)) -> 0.3086067 | R29: =R11/SQRT(SUM($R$16:$R$20)) -> 0.4472136
E31: Tabel Normalisasi Terbobot
E32: Alternatives Supplier | F32: EKONOMI | J32: LINGKUNGAN | M32: SOSIAL | P32: ETIKA | S32: Jumlah Baris
F33: Kualitas | G33: Harga | H33: Delivery | I33: TKDN | J33: Eco-design | K33: Sistem Man. Lingkungan | L33: Green Image | M33: Sistem K3 | N33: CSR | O33: Education & Training | P33: CoC | Q33: CoI | R33: Transparansi Akuntansi Bisnis
E34: S1 | F34: =F25*$C$4 -> 0.052105117 | G34: =G25*$C$5 -> 0.031446693 | H34: =H25*$C$6 -> 0.014179468 | I34: =I25*$C$7 -> 0.010481718 | J34: =J25*$C$8 -> 0.022322232 | K34: =K25*$C$9 -> 0.036162976 | L34: =L25*$C$10 -> 0.033287122 | M34: =M25*$C$11 -> 0.08705891 | N34: =N25*$C$12 -> 0.011355333 | O34: =O25*$C$13 -> 0.043765048 | P34: =P25*$C$14 -> 0.055220924 | Q34: =Q25*$C$15 -> 0.021537098 | R34: =R25*$C$16 -> 0.0082540199 | S34: =SUM(F34:R34) -> 0.42717666
E35: S2 | F35: =F26*$C$4 -> 0.06252614 | G35: =G26*$C$5 -> 0.029350246 | H35: =H26*$C$6 -> 0.015754965 | I35: =I26*$C$7 -> 0.011979106 | J35: =J26*$C$8 -> 0.009566671 | K35: =K26*$C$9 -> 0.060271627 | L35: =L26*$C$10 -> 0.023776516 | M35: =M26*$C$11 -> 0.043529455 | N35: =N26*$C$12 -> 0.0068131996 | O35: =O26*$C$13 -> 0.027353155 | P35: =P26*$C$14 -> 0.046017437 | Q35: =Q26*$C$15 -> 0.053842745 | R35: =R26*$C$16 -> 0.02476206 | S35: =SUM(F35:R35) -> 0.41554332
E36: S3 | F36: =F27*$C$4 -> 0.041684093 | G36: =G27*$C$5 -> 0.033543139 | H36: =H27*$C$6 -> 0.015754965 | I36: =I27*$C$7 -> 0.011380151 | J36: =J27*$C$8 -> 0.015944452 | K36: =K27*$C$9 -> 0.060271627 | L36: =L27*$C$10 -> 0.028531819 | M36: =M27*$C$11 -> 0.043529455 | N36: =N27*$C$12 -> 0.015897466 | O36: =O27*$C$13 -> 0.027353155 | P36: =P27*$C$14 -> 0.064424412 | Q36: =Q27*$C$15 -> 0.032305647 | R36: =R27*$C$16 -> 0.0412701 | S36: =SUM(F36:R36) -> 0.43189048
E37: S4 | F37: =F28*$C$4 -> 0.057315628 | G37: =G28*$C$5 -> 0.030049062 | H37: =H28*$C$6 -> 0.017330461 | I37: =I28*$C$7 -> 0.013476495 | J37: =J28*$C$8 -> 0.015944452 | K37: =K28*$C$9 -> 0.084380278 | L37: =L28*$C$10 -> 0.028531819 | M37: =M28*$C$11 -> 0.08705891 | N37: =N28*$C$12 -> 0.011355333 | O37: =O28*$C$13 -> 0.038294417 | P37: =P28*$C$14 -> 0.064424412 | Q37: =Q28*$C$15 -> 0 | R37: =R28*$C$16 -> 0.0082540199 | S37: =SUM(F37:R37) -> 0.45641529
E38: S5 | F38: =F29*$C$4 -> 0.046894605 | G38: =G29*$C$5 -> 0.032145508 | H38: =H29*$C$6 -> 0.017330461 | I38: =I29*$C$7 -> 0.011080673 | J38: =J29*$C$8 -> 0.015944452 | K38: =K29*$C$9 -> 0.084380278 | L38: =L29*$C$10 -> 0.023776516 | M38: =M29*$C$11 -> 0.043529455 | N38: =N29*$C$12 -> 0.015897466 | O38: =O29*$C$13 -> 0.032823786 | P38: =P29*$C$14 -> 0.046017437 | Q38: =Q29*$C$15 -> 0.021537098 | R38: =R29*$C$16 -> 0.02476206 | S38: =SUM(F38:R38) -> 0.41611979
E39: Min | F39: =MIN(F34:F38) -> 0.041684093 | G39: =MIN(G34:G38) -> 0.029350246 | H39: =MIN(H34:H38) -> 0.014179468 | I39: =MIN(I34:I38) -> 0.010481718 | J39: =MIN(J34:J38) -> 0.009566671 | K39: =MIN(K34:K38) -> 0.036162976 | L39: =MIN(L34:L38) -> 0.023776516 | M39: =MIN(M34:M38) -> 0.043529455 | ... R39: =MIN(R34:R38) -> 0.0082540199 | S39: =SUM(F39:R39) -> 0.29716896 | T39: Solusi Ideal -
E40: Max | F40: =MAX(F34:F38) -> 0.06252614 | G40: =MAX(G34:G38) -> 0.033543139 | H40: =MAX(H34:H38) -> 0.017330461 | I40: =MAX(I34:I38) -> 0.013476495 | J40: =MAX(J34:J38) -> 0.022322232 | K40: =MAX(K34:K38) -> 0.084380278 | L40: =MAX(L34:L38) -> 0.033287122 | M40: =MAX(M34:M38) -> 0.08705891 | ... R40: =MAX(R34:R38) -> 0.0412701 | S40: =SUM(F40:R40) -> 0.57312455 | T40: Solusi Ideal +
E42: Jarak Alternatif Solusi Ideal + | I42: Jarak Alternatif Solusi Ideal - | L42: Nilai Preferensi
E43: Alternatives | F43: S+ | I43: Alternatives | J43: S- | L43: Alternatives | M43: Preferensi | N43: Ranking
E44: S1 | F44: =$S$40-S34 -> 0.14594789 | I44: S1 | J44: =$S$39-S34 -> -0.1300077 | L44: S1 | M44: =J44/(F44+J44) -> -8.1559725 | N44: 4
...

Sheet Detail Expert
B1: Detail Respondence
B3: Experts | C3: Pengalaman | D3: Divisi | E3: Role | F3: Posisi
B4: Expert 1 | C4: > 15 tahun | D4: Drilling and Well Intervention (Subsurface) | E4: Drilling and Well Operation | F4: Senior Analyst / Assistant Manager
B5: Expert 2 | C5: > 15 tahun | D5: Procurement and Supply Chain Management | E5: Contract, Procurement & Logistic | F5: Senior Analyst / Assistant Manager
B6: Expert 3 | C6: > 12 tahun | D6: Communication Relation Community | E6: Community Development | F6: Senior Coordinator
